2018-01-13 09:04:02,630 1 INFO ? odoo: Odoo version 11.0-20171030
2018-01-13 09:04:02,631 1 INFO ? odoo: Using configuration file at /etc/odoo/odoo.conf
2018-01-13 09:04:02,631 1 INFO ? odoo: addons paths: ['/var/lib/odoo/addons/11.0', '/mnt/extra-addons', '/usr/lib/python3/dist-packages/odoo/addons']
2018-01-13 09:04:02,631 1 INFO ? odoo: database: odoo@db:5432
2018-01-13 09:04:02,732 1 INFO ? odoo.service.server: HTTP service (werkzeug) running on 0.0.0.0:8069
2018-01-13 09:04:03,548 1 INFO ? odoo.addons.base.ir.ir_actions_report: Will use the Wkhtmltopdf binary at /usr/local/bin/wkhtmltopdf
2018-01-13 09:04:11,360 1 INFO ? odoo.http: HTTP Configuring static files
2018-01-13 09:04:12,173 1 INFO odoo_logistic odoo.modules.loading: loading 1 modules...
2018-01-13 09:04:12,223 1 INFO odoo_logistic odoo.modules.loading: 1 modules loaded in 0.05s, 0 queries
2018-01-13 09:04:12,262 1 INFO odoo_logistic odoo.modules.loading: loading 11 modules...
2018-01-13 09:04:12,340 1 INFO odoo_logistic odoo.modules.loading: 11 modules loaded in 0.08s, 0 queries
2018-01-13 09:04:12,834 1 INFO odoo_logistic odoo.modules.loading: Modules loaded.
2018-01-13 09:04:13,007 1 INFO odoo_logistic odoo.addons.base.ir.ir_http: Generating routing map
2018-01-13 09:04:13,070 1 INFO odoo_logistic werkzeug: 192.168.177.1 - - [13/Jan/2018 09:04:13] "GET / HTTP/1.1" 200 -
2018-01-13 09:04:13,585 1 INFO odoo_logistic werkzeug: 192.168.177.1 - - [13/Jan/2018 09:04:13] "GET /web HTTP/1.1" 303 -
2018-01-13 09:04:13,828 1 INFO odoo_logistic werkzeug: 192.168.177.1 - - [13/Jan/2018 09:04:13] "GET /favicon.ico HTTP/1.1" 404 -
2018-01-13 09:04:16,005 1 INFO odoo_logistic odoo.models.unlink: User #1 deleted ir.attachment records with IDs: [347]
2018-01-13 09:04:20,164 1 INFO odoo_logistic odoo.models.unlink: User #1 deleted ir.attachment records with IDs: [351]
2018-01-13 09:04:20,374 1 INFO odoo_logistic werkzeug: 192.168.177.1 - - [13/Jan/2018 09:04:20] "GET /web/login HTTP/1.1" 200 -
2018-01-13 09:04:20,618 1 INFO odoo_logistic werkzeug: 192.168.177.1 - - [13/Jan/2018 09:04:20] "GET /web/content/360-da4f5f4/web.assets_frontend.js HTTP/1.1" 200 -
2018-01-13 09:04:20,635 1 INFO odoo_logistic werkzeug: 192.168.177.1 - - [13/Jan/2018 09:04:20] "GET /web/content/357-d17315f/web.assets_common.0.css HTTP/1.1" 200 -
2018-01-13 09:04:20,639 1 INFO odoo_logistic werkzeug: 192.168.177.1 - - [13/Jan/2018 09:04:20] "GET /web/content/358-da4f5f4/web.assets_frontend.0.css HTTP/1.1" 200 -
2018-01-13 09:04:20,722 1 INFO odoo_logistic werkzeug: 192.168.177.1 - - [13/Jan/2018 09:04:20] "GET /web/content/359-d17315f/web.assets_common.js HTTP/1.1" 200 -
2018-01-13 09:04:20,968 1 INFO odoo_logistic werkzeug: 192.168.177.1 - - [13/Jan/2018 09:04:20] "GET /web/webclient/qweb?mods= HTTP/1.1" 200 -
2018-01-13 09:04:20,976 1 INFO odoo_logistic werkzeug: 192.168.177.1 - - [13/Jan/2018 09:04:20] "POST /web/webclient/bootstrap_translations HTTP/1.1" 200 -
2018-01-13 09:04:28,576 1 INFO odoo_logistic werkzeug: 192.168.177.1 - - [13/Jan/2018 09:04:28] "POST /web/login HTTP/1.1" 200 -
2018-01-13 09:04:29,378 1 INFO odoo_logistic odoo.addons.base.ir.ir_attachment: _read_file reading /var/lib/odoo/filestore/odoo_logistic/bd/bd402be51199b5dbe8b8019aaa197ff08384cf31
Traceback (most recent call last):
  File "/usr/lib/python3/dist-packages/odoo/tools/cache.py", line 84, in lookup
    r = d[key]
  File "/usr/lib/python3/dist-packages/odoo/tools/func.py", line 68, in wrapper
    return func(self, *args, **kwargs)
  File "/usr/lib/python3/dist-packages/odoo/tools/lru.py", line 44, in __getitem__
    a = self.d[obj].me
KeyError: ('ir.ui.menu', <function IrUiMenu.load_menus at 0x7f29b4125598>, 1, False, ('en_US',))

During handling of the above exception, another exception occurred:

Traceback (most recent call last):
  File "/usr/lib/python3/dist-packages/odoo/fields.py", line 944, in __get__
    value = record.env.cache.get(record, self)
  File "/usr/lib/python3/dist-packages/odoo/api.py", line 960, in get
    value = self._data[field][record.id][key]
KeyError: <odoo.api.Environment object at 0x7f2991da6860>

During handling of the above exception, another exception occurred:

Traceback (most recent call last):
  File "/usr/lib/python3/dist-packages/odoo/addons/base/ir/ir_attachment.py", line 100, in _file_read
    r = base64.b64encode(open(full_path,'rb').read())
FileNotFoundError: [Errno 2] No such file or directory: '/var/lib/odoo/filestore/odoo_logistic/bd/bd402be51199b5dbe8b8019aaa197ff08384cf31'
2018-01-13 09:04:29,397 1 INFO odoo_logistic odoo.addons.base.ir.ir_attachment: _read_file reading /var/lib/odoo/filestore/odoo_logistic/9c/9c47efe86d2251992fa7a68a4e8a206f33e5949d
Traceback (most recent call last):
  File "/usr/lib/python3/dist-packages/odoo/tools/cache.py", line 84, in lookup
    r = d[key]
  File "/usr/lib/python3/dist-packages/odoo/tools/func.py", line 68, in wrapper
    return func(self, *args, **kwargs)
  File "/usr/lib/python3/dist-packages/odoo/tools/lru.py", line 44, in __getitem__
    a = self.d[obj].me
KeyError: ('ir.ui.menu', <function IrUiMenu.load_menus at 0x7f29b4125598>, 1, False, ('en_US',))

During handling of the above exception, another exception occurred:

Traceback (most recent call last):
  File "/usr/lib/python3/dist-packages/odoo/fields.py", line 944, in __get__
    value = record.env.cache.get(record, self)
  File "/usr/lib/python3/dist-packages/odoo/api.py", line 960, in get
    value = self._data[field][record.id][key]
KeyError: <odoo.api.Environment object at 0x7f2991da6860>

During handling of the above exception, another exception occurred:

Traceback (most recent call last):
  File "/usr/lib/python3/dist-packages/odoo/addons/base/ir/ir_attachment.py", line 100, in _file_read
    r = base64.b64encode(open(full_path,'rb').read())
FileNotFoundError: [Errno 2] No such file or directory: '/var/lib/odoo/filestore/odoo_logistic/9c/9c47efe86d2251992fa7a68a4e8a206f33e5949d'
2018-01-13 09:04:34,404 1 INFO odoo_logistic odoo.models.unlink: User #1 deleted ir.attachment records with IDs: [349, 348]
2018-01-13 09:04:35,390 1 INFO odoo_logistic odoo.models.unlink: User #1 deleted ir.attachment records with IDs: [355]
2018-01-13 09:04:36,800 1 INFO odoo_logistic odoo.models.unlink: User #1 deleted ir.attachment records with IDs: [356]
2018-01-13 09:04:38,174 1 INFO odoo_logistic odoo.models.unlink: User #1 deleted ir.attachment records with IDs: [352]
2018-01-13 09:04:38,479 1 INFO odoo_logistic odoo.models.unlink: User #1 deleted ir.attachment records with IDs: [353]
2018-01-13 09:04:38,707 1 INFO odoo_logistic odoo.models.unlink: User #1 deleted ir.attachment records with IDs: [354]
2018-01-13 09:04:38,923 1 INFO odoo_logistic werkzeug: 192.168.177.1 - - [13/Jan/2018 09:04:38] "GET /web HTTP/1.1" 200 -
2018-01-13 09:04:39,064 1 INFO odoo_logistic werkzeug: 192.168.177.1 - - [13/Jan/2018 09:04:39] "GET /web/content/362-05508b3/web.assets_backend.1.css HTTP/1.1" 200 -
2018-01-13 09:04:39,078 1 INFO odoo_logistic werkzeug: 192.168.177.1 - - [13/Jan/2018 09:04:39] "GET /web/content/363-cade463/web_editor.summernote.0.css HTTP/1.1" 200 -
2018-01-13 09:04:39,096 1 INFO odoo_logistic werkzeug: 192.168.177.1 - - [13/Jan/2018 09:04:39] "GET /web/content/361-05508b3/web.assets_backend.0.css HTTP/1.1" 200 -
2018-01-13 09:04:39,139 1 INFO odoo_logistic werkzeug: 192.168.177.1 - - [13/Jan/2018 09:04:39] "GET /web/content/364-c8e0d48/web_editor.assets_editor.0.css HTTP/1.1" 200 -
2018-01-13 09:04:39,198 1 INFO odoo_logistic werkzeug: 192.168.177.1 - - [13/Jan/2018 09:04:39] "GET /web/content/366-cade463/web_editor.summernote.js HTTP/1.1" 200 -
2018-01-13 09:04:39,238 1 INFO odoo_logistic werkzeug: 192.168.177.1 - - [13/Jan/2018 09:04:39] "GET /web/content/365-05508b3/web.assets_backend.js HTTP/1.1" 200 -
2018-01-13 09:04:39,248 1 INFO odoo_logistic werkzeug: 192.168.177.1 - - [13/Jan/2018 09:04:39] "GET /web/content/367-c8e0d48/web_editor.assets_editor.js HTTP/1.1" 200 -
2018-01-13 09:04:39,908 1 INFO odoo_logistic werkzeug: 192.168.177.1 - - [13/Jan/2018 09:04:39] "GET /web/webclient/qweb?mods=web,base,web_tour,web_planner,base_import,iap,web_kanban_gauge,web_editor,web_settings_dashboard,web_diagram HTTP/1.1" 200 -
2018-01-13 09:04:39,999 1 INFO odoo_logistic werkzeug: 192.168.177.1 - - [13/Jan/2018 09:04:39] "POST /web/dataset/call HTTP/1.1" 200 -
2018-01-13 09:04:40,019 1 INFO odoo_logistic werkzeug: 192.168.177.1 - - [13/Jan/2018 09:04:40] "POST /web/webclient/translations HTTP/1.1" 200 -
2018-01-13 09:04:40,132 1 INFO odoo_logistic werkzeug: 192.168.177.1 - - [13/Jan/2018 09:04:40] "POST /web/dataset/call_kw/web.planner/search_read HTTP/1.1" 200 -
2018-01-13 09:04:40,145 1 INFO odoo_logistic werkzeug: 192.168.177.1 - - [13/Jan/2018 09:04:40] "POST /web/dataset/call_kw/res.users/read HTTP/1.1" 200 -
2018-01-13 09:04:40,160 1 INFO odoo_logistic odoo.addons.base.ir.ir_attachment: _read_file reading /var/lib/odoo/filestore/odoo_logistic/49/492128466be63cd22c92773235330fefbf762bec
Traceback (most recent call last):
  File "/usr/lib/python3/dist-packages/odoo/fields.py", line 944, in __get__
    value = record.env.cache.get(record, self)
  File "/usr/lib/python3/dist-packages/odoo/api.py", line 960, in get
    value = self._data[field][record.id][key]
KeyError: <odoo.api.Environment object at 0x7f2991da5208>

During handling of the above exception, another exception occurred:

Traceback (most recent call last):
  File "/usr/lib/python3/dist-packages/odoo/fields.py", line 944, in __get__
    value = record.env.cache.get(record, self)
  File "/usr/lib/python3/dist-packages/odoo/api.py", line 960, in get
    value = self._data[field][record.id][key]
KeyError: <odoo.api.Environment object at 0x7f2991da5208>

During handling of the above exception, another exception occurred:

Traceback (most recent call last):
  File "/usr/lib/python3/dist-packages/odoo/fields.py", line 944, in __get__
    value = record.env.cache.get(record, self)
  File "/usr/lib/python3/dist-packages/odoo/api.py", line 960, in get
    value = self._data[field][record.id][key]
KeyError: <odoo.api.Environment object at 0x7f2991da5208>

During handling of the above exception, another exception occurred:

Traceback (most recent call last):
  File "/usr/lib/python3/dist-packages/odoo/addons/base/ir/ir_attachment.py", line 100, in _file_read
    r = base64.b64encode(open(full_path,'rb').read())
FileNotFoundError: [Errno 2] No such file or directory: '/var/lib/odoo/filestore/odoo_logistic/49/492128466be63cd22c92773235330fefbf762bec'
2018-01-13 09:04:40,237 1 INFO odoo_logistic werkzeug: 192.168.177.1 - - [13/Jan/2018 09:04:40] "GET /web/image?model=res.users&field=image_small&id=1 HTTP/1.1" 200 -
2018-01-13 09:04:40,370 1 INFO odoo_logistic werkzeug: 192.168.177.1 - - [13/Jan/2018 09:04:40] "POST /web/action/load HTTP/1.1" 200 -
2018-01-13 09:04:40,617 1 INFO odoo_logistic werkzeug: 192.168.177.1 - - [13/Jan/2018 09:04:40] "POST /web/dataset/call_kw/ir.module.module/load_views HTTP/1.1" 200 -
2018-01-13 09:04:40,734 1 INFO odoo_logistic werkzeug: 192.168.177.1 - - [13/Jan/2018 09:04:40] "POST /web/dataset/search_read HTTP/1.1" 200 -
2018-01-13 09:04:43,607 1 INFO odoo_logistic werkzeug: 192.168.177.1 - - [13/Jan/2018 09:04:43] "POST /web/action/load HTTP/1.1" 200 -
2018-01-13 09:04:43,666 1 INFO odoo_logistic werkzeug: 192.168.177.1 - - [13/Jan/2018 09:04:43] "POST /web_settings_dashboard/data HTTP/1.1" 200 -
2018-01-13 09:04:43,744 1 INFO odoo_logistic werkzeug: 192.168.177.1 - - [13/Jan/2018 09:04:43] "POST /web/dataset/call_kw/web.planner/search_read HTTP/1.1" 200 -
2018-01-13 09:04:43,758 1 INFO odoo_logistic werkzeug: 192.168.177.1 - - [13/Jan/2018 09:04:43] "POST /web/dataset/call_kw HTTP/1.1" 200 -
2018-01-13 09:04:45,609 1 INFO odoo_logistic odoo.addons.base.ir.ir_attachment: _read_file reading /var/lib/odoo/filestore/odoo_logistic/bd/bd402be51199b5dbe8b8019aaa197ff08384cf31
Traceback (most recent call last):
  File "/usr/lib/python3/dist-packages/odoo/tools/cache.py", line 84, in lookup
    r = d[key]
  File "/usr/lib/python3/dist-packages/odoo/tools/func.py", line 68, in wrapper
    return func(self, *args, **kwargs)
  File "/usr/lib/python3/dist-packages/odoo/tools/lru.py", line 44, in __getitem__
    a = self.d[obj].me
KeyError: ('ir.ui.menu', <function IrUiMenu.load_menus at 0x7f29b4125598>, 1, True, ('en_US',))

During handling of the above exception, another exception occurred:

Traceback (most recent call last):
  File "/usr/lib/python3/dist-packages/odoo/fields.py", line 944, in __get__
    value = record.env.cache.get(record, self)
  File "/usr/lib/python3/dist-packages/odoo/api.py", line 960, in get
    value = self._data[field][record.id][key]
KeyError: <odoo.api.Environment object at 0x7f2991dce828>

During handling of the above exception, another exception occurred:

Traceback (most recent call last):
  File "/usr/lib/python3/dist-packages/odoo/addons/base/ir/ir_attachment.py", line 100, in _file_read
    r = base64.b64encode(open(full_path,'rb').read())
FileNotFoundError: [Errno 2] No such file or directory: '/var/lib/odoo/filestore/odoo_logistic/bd/bd402be51199b5dbe8b8019aaa197ff08384cf31'
2018-01-13 09:04:45,614 1 INFO odoo_logistic odoo.addons.base.ir.ir_attachment: _read_file reading /var/lib/odoo/filestore/odoo_logistic/9c/9c47efe86d2251992fa7a68a4e8a206f33e5949d
Traceback (most recent call last):
  File "/usr/lib/python3/dist-packages/odoo/tools/cache.py", line 84, in lookup
    r = d[key]
  File "/usr/lib/python3/dist-packages/odoo/tools/func.py", line 68, in wrapper
    return func(self, *args, **kwargs)
  File "/usr/lib/python3/dist-packages/odoo/tools/lru.py", line 44, in __getitem__
    a = self.d[obj].me
KeyError: ('ir.ui.menu', <function IrUiMenu.load_menus at 0x7f29b4125598>, 1, True, ('en_US',))

During handling of the above exception, another exception occurred:

Traceback (most recent call last):
  File "/usr/lib/python3/dist-packages/odoo/fields.py", line 944, in __get__
    value = record.env.cache.get(record, self)
  File "/usr/lib/python3/dist-packages/odoo/api.py", line 960, in get
    value = self._data[field][record.id][key]
KeyError: <odoo.api.Environment object at 0x7f2991dce828>

During handling of the above exception, another exception occurred:

Traceback (most recent call last):
  File "/usr/lib/python3/dist-packages/odoo/addons/base/ir/ir_attachment.py", line 100, in _file_read
    r = base64.b64encode(open(full_path,'rb').read())
FileNotFoundError: [Errno 2] No such file or directory: '/var/lib/odoo/filestore/odoo_logistic/9c/9c47efe86d2251992fa7a68a4e8a206f33e5949d'
2018-01-13 09:04:46,430 1 INFO odoo_logistic werkzeug: 192.168.177.1 - - [13/Jan/2018 09:04:46] "GET /web?debug HTTP/1.1" 200 -
2018-01-13 09:04:47,190 1 INFO odoo_logistic werkzeug: 192.168.177.1 - - [13/Jan/2018 09:04:47] "GET /web/webclient/qweb?mods=web,base,web_tour,web_planner,base_import,iap,web_kanban_gauge,web_editor,web_settings_dashboard,web_diagram HTTP/1.1" 200 -
2018-01-13 09:04:47,270 1 INFO odoo_logistic werkzeug: 192.168.177.1 - - [13/Jan/2018 09:04:47] "POST /web/dataset/call HTTP/1.1" 200 -
2018-01-13 09:04:47,340 1 INFO odoo_logistic werkzeug: 192.168.177.1 - - [13/Jan/2018 09:04:47] "POST /web/webclient/translations HTTP/1.1" 200 -
2018-01-13 09:04:47,406 1 INFO odoo_logistic werkzeug: 192.168.177.1 - - [13/Jan/2018 09:04:47] "POST /web/dataset/call_kw/res.users/check_access_rights HTTP/1.1" 200 -
2018-01-13 09:04:47,419 1 INFO odoo_logistic odoo.addons.base.ir.ir_attachment: _read_file reading /var/lib/odoo/filestore/odoo_logistic/49/492128466be63cd22c92773235330fefbf762bec
Traceback (most recent call last):
  File "/usr/lib/python3/dist-packages/odoo/fields.py", line 944, in __get__
    value = record.env.cache.get(record, self)
  File "/usr/lib/python3/dist-packages/odoo/api.py", line 960, in get
    value = self._data[field][record.id][key]
KeyError: <odoo.api.Environment object at 0x7f29af44e630>

During handling of the above exception, another exception occurred:

Traceback (most recent call last):
  File "/usr/lib/python3/dist-packages/odoo/fields.py", line 944, in __get__
    value = record.env.cache.get(record, self)
  File "/usr/lib/python3/dist-packages/odoo/api.py", line 960, in get
    value = self._data[field][record.id][key]
KeyError: <odoo.api.Environment object at 0x7f29af44e630>

During handling of the above exception, another exception occurred:

Traceback (most recent call last):
  File "/usr/lib/python3/dist-packages/odoo/fields.py", line 944, in __get__
    value = record.env.cache.get(record, self)
  File "/usr/lib/python3/dist-packages/odoo/api.py", line 960, in get
    value = self._data[field][record.id][key]
KeyError: <odoo.api.Environment object at 0x7f29af44e630>

During handling of the above exception, another exception occurred:

Traceback (most recent call last):
  File "/usr/lib/python3/dist-packages/odoo/addons/base/ir/ir_attachment.py", line 100, in _file_read
    r = base64.b64encode(open(full_path,'rb').read())
FileNotFoundError: [Errno 2] No such file or directory: '/var/lib/odoo/filestore/odoo_logistic/49/492128466be63cd22c92773235330fefbf762bec'
2018-01-13 09:04:47,434 1 INFO odoo_logistic werkzeug: 192.168.177.1 - - [13/Jan/2018 09:04:47] "POST /web/dataset/call_kw/res.users/has_group HTTP/1.1" 200 -
2018-01-13 09:04:47,444 1 INFO odoo_logistic werkzeug: 192.168.177.1 - - [13/Jan/2018 09:04:47] "GET /web/image?model=res.users&field=image_small&id=1 HTTP/1.1" 304 -
2018-01-13 09:04:47,471 1 INFO odoo_logistic werkzeug: 192.168.177.1 - - [13/Jan/2018 09:04:47] "POST /web/dataset/call_kw/ir.ui.view/check_access_rights HTTP/1.1" 200 -
2018-01-13 09:04:47,473 1 INFO odoo_logistic werkzeug: 192.168.177.1 - - [13/Jan/2018 09:04:47] "POST /web/dataset/call_kw/ir.model.data/xmlid_to_res_id HTTP/1.1" 200 -
2018-01-13 09:04:47,475 1 INFO odoo_logistic werkzeug: 192.168.177.1 - - [13/Jan/2018 09:04:47] "POST /web/dataset/call_kw/web.planner/search_read HTTP/1.1" 200 -
2018-01-13 09:04:47,483 1 INFO odoo_logistic werkzeug: 192.168.177.1 - - [13/Jan/2018 09:04:47] "POST /web/dataset/call_kw/res.users/read HTTP/1.1" 200 -
2018-01-13 09:04:47,578 1 INFO odoo_logistic werkzeug: 192.168.177.1 - - [13/Jan/2018 09:04:47] "POST /web/action/load HTTP/1.1" 200 -
2018-01-13 09:04:47,791 1 INFO odoo_logistic werkzeug: 192.168.177.1 - - [13/Jan/2018 09:04:47] "POST /web/dataset/call_kw/ir.module.module/load_views HTTP/1.1" 200 -
2018-01-13 09:04:47,892 1 INFO odoo_logistic werkzeug: 192.168.177.1 - - [13/Jan/2018 09:04:47] "POST /web/dataset/search_read HTTP/1.1" 200 -
2018-01-13 09:04:49,198 1 INFO odoo_logistic werkzeug: 192.168.177.1 - - [13/Jan/2018 09:04:49] "POST /web/action/load HTTP/1.1" 200 -
2018-01-13 09:04:49,267 1 INFO odoo_logistic werkzeug: 192.168.177.1 - - [13/Jan/2018 09:04:49] "POST /web/dataset/call_kw/base.module.update/load_views HTTP/1.1" 200 -
2018-01-13 09:04:49,288 1 INFO odoo_logistic werkzeug: 192.168.177.1 - - [13/Jan/2018 09:04:49] "POST /web/dataset/call_kw/base.module.update/default_get HTTP/1.1" 200 -
2018-01-13 09:04:49,345 1 INFO ? werkzeug: 192.168.177.1 - - [13/Jan/2018 09:04:49] "GET /web/static/src/xml/dialog.xml?debug=1515834288476 HTTP/1.1" 200 -
2018-01-13 09:04:49,439 1 INFO odoo_logistic werkzeug: 192.168.177.1 - - [13/Jan/2018 09:04:49] "POST /web/dataset/call_kw/res.users/check_access_rights HTTP/1.1" 200 -
2018-01-13 09:04:49,449 1 INFO odoo_logistic werkzeug: 192.168.177.1 - - [13/Jan/2018 09:04:49] "POST /web/dataset/call_kw/ir.model.data/xmlid_to_res_id HTTP/1.1" 200 -
2018-01-13 09:04:49,461 1 INFO odoo_logistic werkzeug: 192.168.177.1 - - [13/Jan/2018 09:04:49] "POST /web/dataset/call_kw/ir.ui.view/check_access_rights HTTP/1.1" 200 -
2018-01-13 09:04:50,587 1 INFO odoo_logistic werkzeug: 192.168.177.1 - - [13/Jan/2018 09:04:50] "POST /web/dataset/call_kw/base.module.update/create HTTP/1.1" 200 -
2018-01-13 09:04:50,616 1 INFO odoo_logistic werkzeug: 192.168.177.1 - - [13/Jan/2018 09:04:50] "POST /web/dataset/call_kw/base.module.update/read HTTP/1.1" 200 -
2018-01-13 09:04:50,635 1 INFO odoo_logistic odoo.addons.base.module.module: ALLOW access to module.update_list on [] to user admin #1 via 192.168.177.1
2018-01-13 09:04:53,358 1 INFO odoo_logistic werkzeug: 192.168.177.1 - - [13/Jan/2018 09:04:53] "POST /web/dataset/call_button HTTP/1.1" 200 -
2018-01-13 09:04:54,920 1 INFO odoo_logistic werkzeug: 192.168.177.1 - - [13/Jan/2018 09:04:54] "POST /web/action/load HTTP/1.1" 200 -
2018-01-13 09:04:54,956 1 INFO odoo_logistic werkzeug: 192.168.177.1 - - [13/Jan/2018 09:04:54] "POST /web/dataset/call_kw/base.module.upgrade/load_views HTTP/1.1" 200 -
2018-01-13 09:04:54,999 1 INFO odoo_logistic werkzeug: 192.168.177.1 - - [13/Jan/2018 09:04:54] "POST /web/dataset/call_kw/base.module.upgrade/default_get HTTP/1.1" 200 -
2018-01-13 09:04:55,122 1 INFO odoo_logistic werkzeug: 192.168.177.1 - - [13/Jan/2018 09:04:55] "POST /web/dataset/call_kw/res.users/check_access_rights HTTP/1.1" 200 -
2018-01-13 09:04:55,144 1 INFO odoo_logistic werkzeug: 192.168.177.1 - - [13/Jan/2018 09:04:55] "POST /web/dataset/call_kw/ir.model.data/xmlid_to_res_id HTTP/1.1" 200 -
2018-01-13 09:04:55,155 1 INFO odoo_logistic werkzeug: 192.168.177.1 - - [13/Jan/2018 09:04:55] "POST /web/dataset/call_kw/ir.ui.view/check_access_rights HTTP/1.1" 200 -
2018-01-13 09:04:56,419 1 INFO odoo_logistic werkzeug: 192.168.177.1 - - [13/Jan/2018 09:04:56] "POST /web/dataset/call_kw/base.module.upgrade/create HTTP/1.1" 200 -
2018-01-13 09:04:56,458 1 INFO odoo_logistic werkzeug: 192.168.177.1 - - [13/Jan/2018 09:04:56] "POST /web/dataset/call_kw/base.module.upgrade/read HTTP/1.1" 200 -
2018-01-13 09:04:56,510 1 INFO odoo_logistic odoo.modules.loading: loading 1 modules...
2018-01-13 09:04:56,564 1 INFO odoo_logistic odoo.modules.loading: 1 modules loaded in 0.05s, 0 queries
2018-01-13 09:04:57,017 1 INFO odoo_logistic odoo.modules.loading: updating modules list
2018-01-13 09:04:57,019 1 INFO odoo_logistic odoo.addons.base.module.module: ALLOW access to module.update_list on [] to user admin #1 via 192.168.177.1
2018-01-13 09:04:58,576 1 INFO odoo_logistic odoo.modules.loading: loading 11 modules...
2018-01-13 09:04:58,615 1 INFO odoo_logistic odoo.modules.loading: 11 modules loaded in 0.04s, 0 queries
2018-01-13 09:04:58,954 1 INFO odoo_logistic odoo.modules.loading: Modules loaded.
2018-01-13 09:04:58,963 1 INFO odoo_logistic werkzeug: 192.168.177.1 - - [13/Jan/2018 09:04:58] "POST /web/dataset/call_button HTTP/1.1" 200 -
2018-01-13 09:05:00,533 1 INFO odoo_logistic odoo.addons.base.ir.ir_http: Generating routing map
2018-01-13 09:05:00,681 1 INFO odoo_logistic werkzeug: 192.168.177.1 - - [13/Jan/2018 09:05:00] "POST /web/action/load HTTP/1.1" 200 -
2018-01-13 09:05:00,695 1 INFO odoo_logistic werkzeug: 192.168.177.1 - - [13/Jan/2018 09:05:00] "POST /web/dataset/call_kw/ir.module.module/get_apps_server HTTP/1.1" 200 -
2018-01-13 09:05:02,629 1 INFO odoo_logistic werkzeug: 192.168.177.1 - - [13/Jan/2018 09:05:02] "POST /web/webclient/version_info HTTP/1.1" 200 -
2018-01-13 09:05:02,702 1 INFO odoo_logistic werkzeug: 192.168.177.1 - - [13/Jan/2018 09:05:02] "POST /web/dataset/call_kw/ir.module.module/search_read HTTP/1.1" 200 -
2018-01-13 09:05:05,357 1 INFO odoo_logistic werkzeug: 192.168.177.1 - - [13/Jan/2018 09:05:05] "POST /web/dataset/call_kw/base.module.update/default_get HTTP/1.1" 200 -
2018-01-13 09:05:05,418 1 INFO odoo_logistic werkzeug: 192.168.177.1 - - [13/Jan/2018 09:05:05] "POST /web/dataset/call_kw/res.users/check_access_rights HTTP/1.1" 200 -
2018-01-13 09:05:05,440 1 INFO odoo_logistic werkzeug: 192.168.177.1 - - [13/Jan/2018 09:05:05] "POST /web/dataset/call_kw/ir.model.data/xmlid_to_res_id HTTP/1.1" 200 -
2018-01-13 09:05:05,455 1 INFO odoo_logistic werkzeug: 192.168.177.1 - - [13/Jan/2018 09:05:05] "POST /web/dataset/call_kw/ir.ui.view/check_access_rights HTTP/1.1" 200 -
2018-01-13 09:05:06,556 1 INFO odoo_logistic werkzeug: 192.168.177.1 - - [13/Jan/2018 09:05:06] "POST /web/dataset/call_kw/base.module.update/create HTTP/1.1" 200 -
2018-01-13 09:05:06,578 1 INFO odoo_logistic werkzeug: 192.168.177.1 - - [13/Jan/2018 09:05:06] "POST /web/dataset/call_kw/base.module.update/read HTTP/1.1" 200 -
2018-01-13 09:05:06,619 1 INFO odoo_logistic odoo.addons.base.module.module: ALLOW access to module.update_list on [] to user admin #1 via 192.168.177.1
2018-01-13 09:05:07,908 1 INFO odoo_logistic werkzeug: 192.168.177.1 - - [13/Jan/2018 09:05:07] "POST /web/dataset/call_button HTTP/1.1" 200 -
2018-01-13 09:05:11,826 1 INFO odoo_logistic werkzeug: 192.168.177.1 - - [13/Jan/2018 09:05:11] "POST /web/dataset/search_read HTTP/1.1" 200 -
2018-01-13 09:05:12,045 1 INFO ? werkzeug: 192.168.177.1 - - [13/Jan/2018 09:05:12] "GET /al_website/static/description/icon.png HTTP/1.1" 200 -
2018-01-13 09:05:13,555 1 INFO odoo_logistic werkzeug: 192.168.177.1 - - [13/Jan/2018 09:05:13] "POST /web/dataset/search_read HTTP/1.1" 200 -
2018-01-13 09:05:17,019 1 INFO odoo_logistic werkzeug: 192.168.177.1 - - [13/Jan/2018 09:05:17] "POST /web/dataset/search_read HTTP/1.1" 200 -
2018-01-13 09:05:28,394 1 INFO odoo_logistic werkzeug: 192.168.177.1 - - [13/Jan/2018 09:05:28] "POST /web/dataset/search_read HTTP/1.1" 200 -
2018-01-13 09:05:32,480 1 INFO odoo_logistic werkzeug: 192.168.177.1 - - [13/Jan/2018 09:05:32] "POST /web/dataset/search_read HTTP/1.1" 200 -
2018-01-13 09:05:34,667 1 INFO odoo_logistic werkzeug: 192.168.177.1 - - [13/Jan/2018 09:05:34] "POST /web/dataset/search_read HTTP/1.1" 200 -
2018-01-13 09:05:37,263 1 INFO odoo_logistic werkzeug: 192.168.177.1 - - [13/Jan/2018 09:05:37] "POST /web/dataset/call_kw/ir.module.module/read HTTP/1.1" 200 -
2018-01-13 09:05:37,318 1 INFO odoo_logistic werkzeug: 192.168.177.1 - - [13/Jan/2018 09:05:37] "POST /web/dataset/call_kw/ir.module.module.dependency/read HTTP/1.1" 200 -
2018-01-13 09:05:37,418 1 INFO odoo_logistic werkzeug: 192.168.177.1 - - [13/Jan/2018 09:05:37] "POST /web/dataset/call_kw/ir.module.category/name_search HTTP/1.1" 200 -
2018-01-13 09:05:37,607 1 INFO ? werkzeug: 192.168.177.1 - - [13/Jan/2018 09:05:37] "GET /base/static/src/css/description.css HTTP/1.1" 200 -
2018-01-13 09:05:37,615 1 INFO ? werkzeug: 192.168.177.1 - - [13/Jan/2018 09:05:37] "GET /web/static/src/img/form_sheetbg.png HTTP/1.1" 200 -
2018-01-13 09:05:40,053 1 INFO odoo_logistic odoo.addons.base.module.module: ALLOW access to module.button_immediate_install on ['al_website'] to user admin #1 via 192.168.177.1
2018-01-13 09:05:40,054 1 INFO odoo_logistic odoo.addons.base.module.module: User #1 triggered module installation
2018-01-13 09:05:40,054 1 INFO odoo_logistic odoo.addons.base.module.module: ALLOW access to module.button_install on ['al_website'] to user admin #1 via 192.168.177.1
2018-01-13 09:05:40,811 1 INFO odoo_logistic odoo.modules.loading: loading 1 modules...
2018-01-13 09:05:40,847 1 INFO odoo_logistic odoo.modules.loading: 1 modules loaded in 0.04s, 0 queries
2018-01-13 09:05:41,106 1 INFO odoo_logistic odoo.modules.loading: updating modules list
2018-01-13 09:05:41,110 1 INFO odoo_logistic odoo.addons.base.module.module: ALLOW access to module.update_list on [] to user admin #1 via 192.168.177.1
2018-01-13 09:05:42,350 1 INFO odoo_logistic odoo.modules.loading: loading 11 modules...
2018-01-13 09:05:42,379 1 INFO odoo_logistic odoo.modules.loading: 11 modules loaded in 0.02s, 0 queries
2018-01-13 09:05:42,396 1 INFO odoo_logistic odoo.modules.loading: loading 23 modules...
2018-01-13 09:05:42,615 1 INFO odoo_logistic odoo.modules.registry: module base_setup: creating or updating database tables
2018-01-13 09:05:43,061 1 INFO ? werkzeug: 192.168.177.1 - - [13/Jan/2018 09:05:43] "GET /web/static/src/img/spin.png HTTP/1.1" 200 -
2018-01-13 09:05:43,520 1 INFO odoo_logistic odoo.modules.loading: loading base_setup/views/res_config_settings_views.xml
2018-01-13 09:05:43,943 1 INFO odoo_logistic odoo.modules.loading: loading base_setup/views/res_partner_views.xml
2018-01-13 09:05:44,288 1 INFO odoo_logistic odoo.modules.registry: module bus: creating or updating database tables
2018-01-13 09:05:44,837 1 INFO odoo_logistic odoo.addons.auth_crypt.models.res_users: Hashing passwords, may be slow for databases with many users...
2018-01-13 09:05:45,175 1 INFO odoo_logistic odoo.modules.loading: loading bus/views/bus.xml
2018-01-13 09:05:45,351 1 INFO odoo_logistic odoo.modules.loading: loading bus/security/ir.model.access.csv
2018-01-13 09:05:45,702 1 INFO odoo_logistic odoo.modules.registry: module http_routing: creating or updating database tables
2018-01-13 09:05:46,221 1 INFO odoo_logistic odoo.modules.registry: module mail: creating or updating database tables
2018-01-13 09:05:47,358 1 INFO odoo_logistic odoo.addons.auth_crypt.models.res_users: Hashing passwords, may be slow for databases with many users...
2018-01-13 09:05:48,936 1 INFO odoo_logistic odoo.models: Storing computed values of mail.activity.res_model
2018-01-13 09:05:48,941 1 INFO odoo_logistic odoo.models: Storing computed values of mail.activity.res_name
2018-01-13 09:05:49,866 1 INFO odoo_logistic odoo.models: Storing computed values of mail.template.model
2018-01-13 09:05:50,147 1 INFO odoo_logistic odoo.models: Storing computed values of res.partner.activity_date_deadline
2018-01-13 09:05:51,156 1 INFO odoo_logistic odoo.models: Storing computed values of email_template.preview.model
2018-01-13 09:05:51,690 1 INFO odoo_logistic odoo.modules.loading: loading mail/wizard/invite_view.xml
2018-01-13 09:05:51,765 1 INFO odoo_logistic odoo.modules.loading: loading mail/wizard/mail_compose_message_view.xml
2018-01-13 09:05:51,923 1 INFO odoo_logistic odoo.modules.loading: loading mail/views/mail_message_subtype_views.xml
2018-01-13 09:05:52,106 1 INFO odoo_logistic odoo.modules.loading: loading mail/views/mail_tracking_views.xml
2018-01-13 09:05:52,276 1 INFO odoo_logistic odoo.modules.loading: loading mail/views/mail_message_views.xml
2018-01-13 09:05:52,522 1 INFO odoo_logistic odoo.modules.loading: loading mail/views/mail_mail_views.xml
2018-01-13 09:05:52,731 1 INFO odoo_logistic odoo.modules.loading: loading mail/views/mail_followers_views.xml
2018-01-13 09:05:52,978 1 INFO odoo_logistic odoo.modules.loading: loading mail/views/mail_channel_views.xml
2018-01-13 09:05:53,492 1 INFO odoo_logistic odoo.modules.loading: loading mail/views/mail_shortcode_views.xml
2018-01-13 09:05:53,687 1 INFO odoo_logistic odoo.modules.loading: loading mail/views/mail_activity_views.xml
2018-01-13 09:05:54,070 1 INFO odoo_logistic odoo.modules.loading: loading mail/views/res_config_settings_views.xml
2018-01-13 09:05:54,155 1 INFO odoo_logistic odoo.modules.loading: loading mail/data/mail_data.xml
2018-01-13 09:05:54,482 1 INFO odoo_logistic odoo.modules.loading: loading mail/data/mail_channel_data.xml
2018-01-13 09:05:54,778 1 INFO odoo_logistic odoo.modules.loading: loading mail/data/mail_shortcode_data.xml
2018-01-13 09:05:54,956 1 INFO odoo_logistic odoo.modules.loading: loading mail/data/mail_activity_data.xml
2018-01-13 09:05:55,056 1 INFO odoo_logistic odoo.modules.loading: loading mail/security/mail_security.xml
2018-01-13 09:05:55,222 1 INFO odoo_logistic odoo.modules.loading: loading mail/security/ir.model.access.csv
2018-01-13 09:05:56,438 1 INFO odoo_logistic odoo.modules.loading: loading mail/views/mail_alias_views.xml
2018-01-13 09:05:56,624 1 INFO odoo_logistic odoo.modules.loading: loading mail/views/res_users_views.xml
2018-01-13 09:05:56,883 1 INFO odoo_logistic odoo.modules.loading: loading mail/views/mail_templates.xml
2018-01-13 09:05:57,490 1 INFO odoo_logistic odoo.modules.loading: loading mail/wizard/email_template_preview_view.xml
2018-01-13 09:05:57,546 1 INFO odoo_logistic odoo.modules.loading: loading mail/views/mail_template_views.xml
2018-01-13 09:05:57,820 1 INFO odoo_logistic odoo.modules.loading: loading mail/views/ir_actions_views.xml
2018-01-13 09:05:57,891 1 INFO odoo_logistic odoo.modules.loading: loading mail/views/ir_model_views.xml
2018-01-13 09:05:58,174 1 INFO odoo_logistic odoo.modules.loading: loading mail/views/res_partner_views.xml
2018-01-13 09:05:58,428 1 INFO odoo_logistic odoo.modules.loading: loading mail/data/mail_demo.xml
2018-01-13 09:05:58,756 1 INFO odoo_logistic odoo.tests: skip sending email in test mode
2018-01-13 09:05:58,770 1 INFO odoo_logistic odoo.addons.mail.models.mail_mail: Mail with ID 1 and Message-Id '<907481625450859.1515834358.474406480789185-openerp-private@6d3c658ff2ed>' successfully sent
2018-01-13 09:05:58,806 1 INFO odoo_logistic odoo.models.unlink: User #1 deleted mail.mail records with IDs: [1]
2018-01-13 09:05:58,807 1 INFO odoo_logistic odoo.addons.mail.models.mail_mail: Sent batch 1 emails via mail server ID #False
2018-01-13 09:05:58,989 1 INFO odoo_logistic odoo.tests: skip sending email in test mode
2018-01-13 09:05:58,997 1 INFO odoo_logistic odoo.addons.mail.models.mail_mail: Mail with ID 2 and Message-Id '<156261728800091.1515834358.831803560256958-openerp-private@6d3c658ff2ed>' successfully sent
2018-01-13 09:05:59,030 1 INFO odoo_logistic odoo.models.unlink: User #1 deleted mail.mail records with IDs: [2]
2018-01-13 09:05:59,031 1 INFO odoo_logistic odoo.addons.mail.models.mail_mail: Sent batch 1 emails via mail server ID #False
2018-01-13 09:05:59,327 1 INFO odoo_logistic odoo.tests: skip sending email in test mode
2018-01-13 09:05:59,334 1 INFO odoo_logistic odoo.addons.mail.models.mail_mail: Mail with ID 3 and Message-Id '<389581343590205.1515834359.117000579833984-openerp-private@6d3c658ff2ed>' successfully sent
2018-01-13 09:05:59,362 1 INFO odoo_logistic odoo.models.unlink: User #1 deleted mail.mail records with IDs: [3]
2018-01-13 09:05:59,363 1 INFO odoo_logistic odoo.addons.mail.models.mail_mail: Sent batch 1 emails via mail server ID #False
2018-01-13 09:05:59,692 1 INFO odoo_logistic odoo.tests: skip sending email in test mode
2018-01-13 09:05:59,699 1 INFO odoo_logistic odoo.addons.mail.models.mail_mail: Mail with ID 4 and Message-Id '<743619850271775.1515834359.438940048217773-openerp-private@6d3c658ff2ed>' successfully sent
2018-01-13 09:05:59,717 1 INFO odoo_logistic odoo.models.unlink: User #1 deleted mail.mail records with IDs: [4]
2018-01-13 09:05:59,718 1 INFO odoo_logistic odoo.addons.mail.models.mail_mail: Sent batch 1 emails via mail server ID #False
2018-01-13 09:06:00,105 1 INFO odoo_logistic odoo.tests: skip sending email in test mode
2018-01-13 09:06:00,112 1 INFO odoo_logistic odoo.addons.mail.models.mail_mail: Mail with ID 5 and Message-Id '<876176709631024.1515834359.955719232559204-openerp-private@6d3c658ff2ed>' successfully sent
2018-01-13 09:06:00,130 1 INFO odoo_logistic odoo.models.unlink: User #1 deleted mail.mail records with IDs: [5]
2018-01-13 09:06:00,130 1 INFO odoo_logistic odoo.addons.mail.models.mail_mail: Sent batch 1 emails via mail server ID #False
2018-01-13 09:06:00,379 1 INFO odoo_logistic odoo.tests: skip sending email in test mode
2018-01-13 09:06:00,386 1 INFO odoo_logistic odoo.addons.mail.models.mail_mail: Mail with ID 6 and Message-Id '<888403232304514.1515834360.167550802230835-openerp-private@6d3c658ff2ed>' successfully sent
2018-01-13 09:06:00,411 1 INFO odoo_logistic odoo.models.unlink: User #1 deleted mail.mail records with IDs: [6]
2018-01-13 09:06:00,412 1 INFO odoo_logistic odoo.addons.mail.models.mail_mail: Sent batch 1 emails via mail server ID #False
2018-01-13 09:06:00,541 1 INFO odoo_logistic odoo.modules.loading: loading mail/data/mail_channel_demo.xml
2018-01-13 09:06:03,227 1 INFO odoo_logistic odoo.modules.registry: module auth_signup: creating or updating database tables
2018-01-13 09:06:03,320 1 INFO odoo_logistic odoo.addons.auth_crypt.models.res_users: Hashing passwords, may be slow for databases with many users...
2018-01-13 09:06:03,591 1 INFO odoo_logistic odoo.modules.loading: loading auth_signup/data/auth_signup_data.xml
2018-01-13 09:06:04,056 1 INFO odoo_logistic odoo.modules.loading: loading auth_signup/views/res_config_settings_views.xml
2018-01-13 09:06:04,251 1 INFO odoo_logistic odoo.modules.loading: loading auth_signup/views/res_users_views.xml
2018-01-13 09:06:04,406 1 INFO odoo_logistic odoo.modules.loading: loading auth_signup/views/auth_signup_login_templates.xml
2018-01-13 09:06:04,634 1 INFO odoo_logistic odoo.modules.loading: loading auth_signup/views/auth_signup_assets.xml
2018-01-13 09:06:05,329 1 INFO odoo_logistic odoo.modules.registry: module fetchmail: creating or updating database tables
2018-01-13 09:06:05,708 1 INFO odoo_logistic odoo.modules.loading: loading fetchmail/data/fetchmail_data.xml
2018-01-13 09:06:05,858 1 INFO odoo_logistic odoo.modules.loading: loading fetchmail/security/ir.model.access.csv
2018-01-13 09:06:05,899 1 INFO odoo_logistic odoo.modules.loading: loading fetchmail/views/fetchmail_views.xml
2018-01-13 09:06:06,169 1 INFO odoo_logistic odoo.modules.loading: loading fetchmail/views/mail_mail_views.xml
2018-01-13 09:06:06,240 1 INFO odoo_logistic odoo.modules.loading: loading fetchmail/views/res_config_settings_views.xml
2018-01-13 09:06:06,860 1 INFO odoo_logistic odoo.modules.registry: module portal: creating or updating database tables
2018-01-13 09:06:07,118 1 INFO odoo_logistic odoo.addons.auth_crypt.models.res_users: Hashing passwords, may be slow for databases with many users...
2018-01-13 09:06:07,631 1 INFO odoo_logistic odoo.modules.loading: loading portal/data/portal_data.xml
2018-01-13 09:06:07,714 1 INFO odoo_logistic odoo.modules.loading: loading portal/views/assets.xml
2018-01-13 09:06:07,973 1 INFO odoo_logistic odoo.modules.loading: loading portal/views/portal_templates.xml
2018-01-13 09:06:08,646 1 INFO odoo_logistic odoo.modules.loading: loading portal/wizard/portal_wizard_views.xml
2018-01-13 09:06:09,365 1 INFO odoo_logistic odoo.modules.registry: module sms: creating or updating database tables
2018-01-13 09:06:09,499 1 INFO odoo_logistic odoo.addons.auth_crypt.models.res_users: Hashing passwords, may be slow for databases with many users...
2018-01-13 09:06:09,773 1 INFO odoo_logistic odoo.modules.loading: loading sms/wizard/send_sms_views.xml
2018-01-13 09:06:09,864 1 INFO odoo_logistic odoo.modules.loading: loading sms/views/res_partner_views.xml
2018-01-13 09:06:10,505 1 INFO odoo_logistic odoo.modules.registry: module website: creating or updating database tables
2018-01-13 09:06:10,667 1 INFO odoo_logistic odoo.models: Computing parent left and right for table website_menu...
2018-01-13 09:06:10,894 1 INFO odoo_logistic odoo.addons.auth_crypt.models.res_users: Hashing passwords, may be slow for databases with many users...
2018-01-13 09:06:11,218 1 INFO odoo_logistic odoo.models: Storing computed values of website.default_lang_code
2018-01-13 09:06:12,353 1 INFO odoo_logistic odoo.modules.loading: loading website/data/website_data.xml
2018-01-13 09:06:13,867 1 INFO odoo_logistic odoo.modules.loading: loading website/security/website_security.xml
2018-01-13 09:06:14,776 1 INFO odoo_logistic odoo.modules.loading: loading website/security/ir.model.access.csv
2018-01-13 09:06:15,149 1 INFO odoo_logistic odoo.modules.loading: loading website/views/website_templates.xml
2018-01-13 09:06:18,107 1 INFO odoo_logistic odoo.modules.loading: loading website/views/website_navbar_templates.xml
2018-01-13 09:06:18,271 1 INFO odoo_logistic odoo.modules.loading: loading website/views/snippets.xml
2018-01-13 09:06:19,981 1 INFO odoo_logistic odoo.modules.loading: loading website/views/website_views.xml
2018-01-13 09:06:20,792 1 INFO odoo_logistic odoo.modules.loading: loading website/views/res_config_settings_views.xml
2018-01-13 09:06:21,085 1 INFO odoo_logistic odoo.modules.loading: loading website/views/ir_actions_views.xml
2018-01-13 09:06:21,415 1 INFO odoo_logistic odoo.modules.loading: loading website/views/res_company_views.xml
2018-01-13 09:06:21,503 1 INFO odoo_logistic odoo.modules.loading: loading website/wizard/base_language_install_views.xml
2018-01-13 09:06:21,659 1 INFO odoo_logistic odoo.modules.loading: loading website/data/web_planner_data.xml
2018-01-13 09:06:21,834 1 INFO odoo_logistic odoo.modules.loading: loading website/data/website_demo.xml
2018-01-13 09:06:25,253 1 INFO odoo_logistic odoo.modules.registry: module al_website: creating or updating database tables
2018-01-13 09:06:25,276 1 INFO odoo_logistic odoo.modules.loading: loading al_website/views/assets.xml
2018-01-13 09:06:25,522 1 INFO odoo_logistic odoo.modules.loading: loading al_website/views/layout.xml
2018-01-13 09:06:26,500 1 INFO odoo_logistic odoo.modules.registry: module website_mail: creating or updating database tables
2018-01-13 09:06:26,916 1 INFO odoo_logistic odoo.modules.loading: loading website_mail/views/website_mail_templates.xml
2018-01-13 09:06:27,343 1 INFO odoo_logistic odoo.modules.loading: loading website_mail/data/mail_channel_data.xml
2018-01-13 09:06:27,785 1 INFO odoo_logistic odoo.modules.loading: loading website_mail/security/website_mail_security.xml
2018-01-13 09:06:28,481 1 INFO odoo_logistic odoo.modules.registry: module website_theme_install: creating or updating database tables
2018-01-13 09:06:28,690 1 INFO odoo_logistic odoo.modules.loading: loading website_theme_install/views/assets.xml
2018-01-13 09:06:28,986 1 INFO odoo_logistic odoo.modules.loading: loading website_theme_install/views/views.xml
2018-01-13 09:06:29,813 1 INFO odoo_logistic odoo.modules.loading: 23 modules loaded in 47.42s, 5 queries
2018-01-13 09:06:30,695 1 INFO odoo_logistic odoo.modules.loading: Modules loaded.
2018-01-13 09:06:30,702 1 INFO odoo_logistic odoo.models: Computing parent left and right for table ir_ui_menu...
2018-01-13 09:06:30,797 1 INFO odoo_logistic odoo.models: Computing parent left and right for table website_menu...
2018-01-13 09:06:30,825 1 INFO odoo_logistic odoo.addons.base.module.module: getting next ir.actions.todo()
2018-01-13 09:06:30,833 1 INFO odoo_logistic odoo.addons.base.module.module: next action is ir.actions.todo(2,)
2018-01-13 09:06:30,912 1 INFO odoo_logistic werkzeug: 192.168.177.1 - - [13/Jan/2018 09:06:30] "POST /web/dataset/call_button HTTP/1.1" 200 -
2018-01-13 09:06:30,925 1 INFO odoo_logistic odoo.addons.base.ir.ir_http: Generating routing map
2018-01-13 09:06:31,087 1 INFO odoo_logistic odoo.addons.base.module.module: ALLOW access to module.update_list on [] to user admin #1 via 192.168.177.1
2018-01-13 09:06:32,993 1 INFO odoo_logistic werkzeug: 192.168.177.1 - - [13/Jan/2018 09:06:32] "POST /web/action/run HTTP/1.1" 200 -
2018-01-13 09:06:33,389 1 INFO odoo_logistic odoo.addons.base.ir.ir_attachment: _read_file reading /var/lib/odoo/filestore/odoo_logistic/bd/bd402be51199b5dbe8b8019aaa197ff08384cf31
Traceback (most recent call last):
  File "/usr/lib/python3/dist-packages/odoo/tools/cache.py", line 84, in lookup
    r = d[key]
  File "/usr/lib/python3/dist-packages/odoo/tools/func.py", line 68, in wrapper
    return func(self, *args, **kwargs)
  File "/usr/lib/python3/dist-packages/odoo/tools/lru.py", line 44, in __getitem__
    a = self.d[obj].me
KeyError: ('ir.ui.menu', <function IrUiMenu.load_menus at 0x7f29b4125598>, 1, True, ('en_US',))

During handling of the above exception, another exception occurred:

Traceback (most recent call last):
  File "/usr/lib/python3/dist-packages/odoo/fields.py", line 944, in __get__
    value = record.env.cache.get(record, self)
  File "/usr/lib/python3/dist-packages/odoo/api.py", line 960, in get
    value = self._data[field][record.id][key]
KeyError: <odoo.api.Environment object at 0x7f29af399400>

During handling of the above exception, another exception occurred:

Traceback (most recent call last):
  File "/usr/lib/python3/dist-packages/odoo/addons/base/ir/ir_attachment.py", line 100, in _file_read
    r = base64.b64encode(open(full_path,'rb').read())
FileNotFoundError: [Errno 2] No such file or directory: '/var/lib/odoo/filestore/odoo_logistic/bd/bd402be51199b5dbe8b8019aaa197ff08384cf31'
2018-01-13 09:06:33,394 1 INFO odoo_logistic odoo.addons.base.ir.ir_attachment: _read_file reading /var/lib/odoo/filestore/odoo_logistic/9c/9c47efe86d2251992fa7a68a4e8a206f33e5949d
Traceback (most recent call last):
  File "/usr/lib/python3/dist-packages/odoo/tools/cache.py", line 84, in lookup
    r = d[key]
  File "/usr/lib/python3/dist-packages/odoo/tools/func.py", line 68, in wrapper
    return func(self, *args, **kwargs)
  File "/usr/lib/python3/dist-packages/odoo/tools/lru.py", line 44, in __getitem__
    a = self.d[obj].me
KeyError: ('ir.ui.menu', <function IrUiMenu.load_menus at 0x7f29b4125598>, 1, True, ('en_US',))

During handling of the above exception, another exception occurred:

Traceback (most recent call last):
  File "/usr/lib/python3/dist-packages/odoo/fields.py", line 944, in __get__
    value = record.env.cache.get(record, self)
  File "/usr/lib/python3/dist-packages/odoo/api.py", line 960, in get
    value = self._data[field][record.id][key]
KeyError: <odoo.api.Environment object at 0x7f29af399400>

During handling of the above exception, another exception occurred:

Traceback (most recent call last):
  File "/usr/lib/python3/dist-packages/odoo/addons/base/ir/ir_attachment.py", line 100, in _file_read
    r = base64.b64encode(open(full_path,'rb').read())
FileNotFoundError: [Errno 2] No such file or directory: '/var/lib/odoo/filestore/odoo_logistic/9c/9c47efe86d2251992fa7a68a4e8a206f33e5949d'
2018-01-13 09:06:35,450 1 INFO odoo_logistic odoo.models.unlink: User #1 deleted ir.attachment records with IDs: [357]
2018-01-13 09:06:41,680 1 INFO odoo_logistic odoo.models.unlink: User #1 deleted ir.attachment records with IDs: [362, 361]
2018-01-13 09:06:43,591 1 INFO odoo_logistic odoo.models.unlink: User #1 deleted ir.attachment records with IDs: [359]
2018-01-13 09:06:45,979 1 INFO odoo_logistic odoo.models.unlink: User #1 deleted ir.attachment records with IDs: [365]
2018-01-13 09:06:46,435 1 INFO odoo_logistic werkzeug: 192.168.177.1 - - [13/Jan/2018 09:06:46] "GET /web?debug=1&reload= HTTP/1.1" 200 -
2018-01-13 09:06:46,584 1 INFO odoo_logistic werkzeug: 192.168.177.1 - - [13/Jan/2018 09:06:46] "GET /web/content/436-03967ef/web.assets_common.0.css HTTP/1.1" 200 -
2018-01-13 09:06:46,614 1 INFO odoo_logistic werkzeug: 192.168.177.1 - - [13/Jan/2018 09:06:46] "GET /web/content/437-809b40e/web.assets_backend.0.css HTTP/1.1" 200 -
2018-01-13 09:06:46,622 1 INFO odoo_logistic werkzeug: 192.168.177.1 - - [13/Jan/2018 09:06:46] "GET /web/content/438-809b40e/web.assets_backend.1.css HTTP/1.1" 200 -
2018-01-13 09:06:46,728 1 INFO odoo_logistic werkzeug: 192.168.177.1 - - [13/Jan/2018 09:06:46] "GET /web/content/439-03967ef/web.assets_common.js HTTP/1.1" 200 -
2018-01-13 09:06:46,741 1 INFO odoo_logistic werkzeug: 192.168.177.1 - - [13/Jan/2018 09:06:46] "GET /web/content/440-809b40e/web.assets_backend.js HTTP/1.1" 200 -
2018-01-13 09:06:47,627 1 INFO odoo_logistic werkzeug: 192.168.177.1 - - [13/Jan/2018 09:06:47] "POST /web/dataset/call HTTP/1.1" 200 -
2018-01-13 09:06:47,837 1 INFO odoo_logistic werkzeug: 192.168.177.1 - - [13/Jan/2018 09:06:47] "GET /web/webclient/qweb?mods=web,base,web_editor,web_planner,bus,web_tour,mail,portal,website,al_website,website_theme_install,base_import,website_mail,web_settings_dashboard,web_kanban_gauge,iap,auth_signup,web_diagram HTTP/1.1" 200 -
2018-01-13 09:06:47,895 1 INFO odoo_logistic werkzeug: 192.168.177.1 - - [13/Jan/2018 09:06:47] "POST /web/webclient/translations HTTP/1.1" 200 -
2018-01-13 09:06:48,062 1 INFO odoo_logistic werkzeug: 192.168.177.1 - - [13/Jan/2018 09:06:48] "POST /web/dataset/call_kw/res.users/check_access_rights HTTP/1.1" 200 -
2018-01-13 09:06:48,122 1 INFO odoo_logistic odoo.addons.base.ir.ir_attachment: _read_file reading /var/lib/odoo/filestore/odoo_logistic/49/492128466be63cd22c92773235330fefbf762bec
Traceback (most recent call last):
  File "/usr/lib/python3/dist-packages/odoo/fields.py", line 944, in __get__
    value = record.env.cache.get(record, self)
  File "/usr/lib/python3/dist-packages/odoo/api.py", line 960, in get
    value = self._data[field][record.id][key]
KeyError: <odoo.api.Environment object at 0x7f29adebe278>

During handling of the above exception, another exception occurred:

Traceback (most recent call last):
  File "/usr/lib/python3/dist-packages/odoo/fields.py", line 944, in __get__
    value = record.env.cache.get(record, self)
  File "/usr/lib/python3/dist-packages/odoo/api.py", line 960, in get
    value = self._data[field][record.id][key]
KeyError: <odoo.api.Environment object at 0x7f29adebe278>

During handling of the above exception, another exception occurred:

Traceback (most recent call last):
  File "/usr/lib/python3/dist-packages/odoo/fields.py", line 944, in __get__
    value = record.env.cache.get(record, self)
  File "/usr/lib/python3/dist-packages/odoo/api.py", line 960, in get
    value = self._data[field][record.id][key]
KeyError: <odoo.api.Environment object at 0x7f29adebe278>

During handling of the above exception, another exception occurred:

Traceback (most recent call last):
  File "/usr/lib/python3/dist-packages/odoo/addons/base/ir/ir_attachment.py", line 100, in _file_read
    r = base64.b64encode(open(full_path,'rb').read())
FileNotFoundError: [Errno 2] No such file or directory: '/var/lib/odoo/filestore/odoo_logistic/49/492128466be63cd22c92773235330fefbf762bec'
2018-01-13 09:06:48,126 1 INFO odoo_logistic werkzeug: 192.168.177.1 - - [13/Jan/2018 09:06:48] "POST /web/dataset/call_kw/res.users/has_group HTTP/1.1" 200 -
2018-01-13 09:06:48,136 1 INFO odoo_logistic werkzeug: 192.168.177.1 - - [13/Jan/2018 09:06:48] "POST /web/dataset/call_kw/ir.ui.view/check_access_rights HTTP/1.1" 200 -
2018-01-13 09:06:48,150 1 INFO odoo_logistic werkzeug: 192.168.177.1 - - [13/Jan/2018 09:06:48] "GET /web/image?model=res.users&field=image_small&id=1 HTTP/1.1" 304 -
2018-01-13 09:06:48,161 1 INFO odoo_logistic werkzeug: 192.168.177.1 - - [13/Jan/2018 09:06:48] "POST /mail/client_action HTTP/1.1" 200 -
2018-01-13 09:06:48,168 1 INFO odoo_logistic werkzeug: 192.168.177.1 - - [13/Jan/2018 09:06:48] "POST /web/dataset/call_kw/ir.model.data/xmlid_to_res_id HTTP/1.1" 200 -
2018-01-13 09:06:48,175 1 INFO odoo_logistic werkzeug: 192.168.177.1 - - [13/Jan/2018 09:06:48] "POST /web/dataset/call_kw/res.users/activity_user_count HTTP/1.1" 200 -
2018-01-13 09:06:48,305 1 INFO ? odoo.addons.bus.models.bus: Bus.loop listen imbus on db postgres
2018-01-13 09:06:48,326 1 INFO odoo_logistic werkzeug: 192.168.177.1 - - [13/Jan/2018 09:06:48] "POST /web/dataset/call_kw/web.planner/search_read HTTP/1.1" 200 -
2018-01-13 09:06:48,455 1 INFO odoo_logistic werkzeug: 192.168.177.1 - - [13/Jan/2018 09:06:48] "POST /web/action/load HTTP/1.1" 200 -
2018-01-13 09:06:48,587 1 INFO odoo_logistic werkzeug: 192.168.177.1 - - [13/Jan/2018 09:06:48] "POST /web/dataset/call_kw/ir.module.module/load_views HTTP/1.1" 200 -
2018-01-13 09:06:48,678 1 INFO odoo_logistic werkzeug: 192.168.177.1 - - [13/Jan/2018 09:06:48] "POST /web/dataset/search_read HTTP/1.1" 200 -
2018-01-13 09:06:48,812 1 INFO odoo_logistic werkzeug: 192.168.177.1 - - [13/Jan/2018 09:06:48] "GET /web/image/435 HTTP/1.1" 301 -
2018-01-13 09:06:48,818 1 INFO odoo_logistic werkzeug: 192.168.177.1 - - [13/Jan/2018 09:06:48] "GET /web/image/433 HTTP/1.1" 301 -
2018-01-13 09:06:48,909 1 INFO ? werkzeug: 192.168.177.1 - - [13/Jan/2018 09:06:48] "GET /theme_bootswatch/static/description/icon.png HTTP/1.1" 200 -
2018-01-13 09:06:48,911 1 INFO ? werkzeug: 192.168.177.1 - - [13/Jan/2018 09:06:48] "GET /theme_default/static/description/icon.png HTTP/1.1" 200 -
2018-01-13 09:06:48,978 1 INFO ? werkzeug: 192.168.177.1 - - [13/Jan/2018 09:06:48] "GET /theme_bootswatch/static/description/bootswatch_screenshot.jpg HTTP/1.1" 200 -
2018-01-13 09:06:48,979 1 INFO ? werkzeug: 192.168.177.1 - - [13/Jan/2018 09:06:48] "GET /theme_default/static/description/theme_default_screenshot.jpg HTTP/1.1" 200 -
2018-01-13 09:07:38,317 1 INFO odoo_logistic werkzeug: 192.168.177.1 - - [13/Jan/2018 09:07:38] "POST /longpolling/poll HTTP/1.1" 200 -
2018-01-13 09:07:40,627 1 INFO odoo_logistic werkzeug: 192.168.177.1 - - [13/Jan/2018 09:07:40] "POST /web/action/load HTTP/1.1" 200 -
2018-01-13 09:07:40,683 1 INFO odoo_logistic werkzeug: 192.168.177.1 - - [13/Jan/2018 09:07:40] "POST /web/action/run HTTP/1.1" 200 -
2018-01-13 09:07:40,788 1 INFO ? werkzeug: 192.168.177.1 - - [13/Jan/2018 09:07:40] "GET /web/static/lib/nvd3/d3.v3.js HTTP/1.1" 200 -
2018-01-13 09:07:40,794 1 INFO ? werkzeug: 192.168.177.1 - - [13/Jan/2018 09:07:40] "GET /web/static/lib/nvd3/nv.d3.css HTTP/1.1" 200 -
2018-01-13 09:07:40,885 1 INFO ? werkzeug: 192.168.177.1 - - [13/Jan/2018 09:07:40] "GET /web/static/lib/nvd3/nv.d3.js HTTP/1.1" 200 -
2018-01-13 09:07:40,971 1 INFO ? werkzeug: 192.168.177.1 - - [13/Jan/2018 09:07:40] "GET /web/static/src/js/libs/nvd3.js HTTP/1.1" 200 -
2018-01-13 09:07:41,211 1 INFO odoo_logistic werkzeug: 192.168.177.1 - - [13/Jan/2018 09:07:41] "POST /website/fetch_dashboard_data HTTP/1.1" 200 -
2018-01-13 09:07:41,254 1 INFO ? werkzeug: 192.168.177.1 - - [13/Jan/2018 09:07:41] "GET /website/static/src/img/website_dashboard_visit_demo.png HTTP/1.1" 200 -
2018-01-13 09:07:42,486 1 INFO odoo_logistic werkzeug: 192.168.177.1 - - [13/Jan/2018 09:07:42] "POST /web/action/load HTTP/1.1" 200 -
2018-01-13 09:07:42,571 1 INFO odoo_logistic werkzeug: 192.168.177.1 - - [13/Jan/2018 09:07:42] "POST /web/dataset/call_kw/ir.module.module/load_views HTTP/1.1" 200 -
2018-01-13 09:07:42,630 1 INFO odoo_logistic werkzeug: 192.168.177.1 - - [13/Jan/2018 09:07:42] "POST /web/dataset/search_read HTTP/1.1" 200 -
2018-01-13 09:07:56,239 1 INFO odoo_logistic odoo.addons.base.module.module: ALLOW access to module.button_immediate_uninstall on [] to user admin #1 via 192.168.177.1
2018-01-13 09:07:56,239 1 INFO odoo_logistic odoo.addons.base.module.module: User #1 triggered module uninstallation
2018-01-13 09:07:56,239 1 INFO odoo_logistic odoo.addons.base.module.module: ALLOW access to module.button_uninstall on [] to user admin #1 via 192.168.177.1
2018-01-13 09:07:56,246 1 INFO odoo_logistic odoo.modules.loading: loading 1 modules...
2018-01-13 09:07:56,295 1 INFO odoo_logistic odoo.modules.loading: 1 modules loaded in 0.05s, 0 queries
2018-01-13 09:07:56,515 1 INFO odoo_logistic odoo.modules.loading: updating modules list
2018-01-13 09:07:56,564 1 INFO odoo_logistic odoo.addons.base.module.module: ALLOW access to module.update_list on [] to user admin #1 via 192.168.177.1
2018-01-13 09:07:57,834 1 INFO odoo_logistic odoo.modules.loading: loading 23 modules...
2018-01-13 09:07:57,949 1 INFO odoo_logistic odoo.modules.loading: 23 modules loaded in 0.11s, 0 queries
2018-01-13 09:07:58,357 1 INFO odoo_logistic odoo.modules.loading: Modules loaded.
2018-01-13 09:07:58,372 1 INFO odoo_logistic odoo.addons.base.module.module: getting next ir.actions.todo()
2018-01-13 09:07:58,380 1 INFO odoo_logistic odoo.addons.base.module.module: ALLOW access to module.button_immediate_install on ['theme_bootswatch'] to user admin #1 via 192.168.177.1
2018-01-13 09:07:58,381 1 INFO odoo_logistic odoo.addons.base.module.module: User #1 triggered module installation
2018-01-13 09:07:58,381 1 INFO odoo_logistic odoo.addons.base.module.module: ALLOW access to module.button_install on ['theme_bootswatch'] to user admin #1 via 192.168.177.1
2018-01-13 09:07:58,697 1 INFO odoo_logistic odoo.modules.loading: loading 1 modules...
2018-01-13 09:07:58,729 1 INFO odoo_logistic odoo.modules.loading: 1 modules loaded in 0.03s, 0 queries
2018-01-13 09:07:58,997 1 INFO odoo_logistic odoo.modules.loading: updating modules list
2018-01-13 09:07:59,010 1 INFO odoo_logistic odoo.addons.base.module.module: ALLOW access to module.update_list on [] to user admin #1 via 192.168.177.1
2018-01-13 09:07:59,493 1 INFO ? werkzeug: 192.168.177.1 - - [13/Jan/2018 09:07:59] "GET /web/static/src/img/spin.png HTTP/1.1" 200 -
2018-01-13 09:08:00,751 1 INFO odoo_logistic odoo.modules.loading: loading 23 modules...
2018-01-13 09:08:00,803 1 INFO odoo_logistic odoo.modules.loading: 23 modules loaded in 0.05s, 0 queries
2018-01-13 09:08:00,810 1 INFO odoo_logistic odoo.modules.loading: loading 24 modules...
2018-01-13 09:08:00,959 1 INFO odoo_logistic odoo.modules.registry: module theme_bootswatch: creating or updating database tables
2018-01-13 09:08:00,985 1 INFO odoo_logistic odoo.modules.loading: loading theme_bootswatch/data/theme_bootswatch_data.xml
2018-01-13 09:08:01,102 1 INFO odoo_logistic odoo.modules.loading: loading theme_bootswatch/views/theme_bootswatch_templates.xml
2018-01-13 09:08:02,693 1 INFO odoo_logistic odoo.modules.loading: 24 modules loaded in 1.88s, 0 queries
2018-01-13 09:08:03,403 1 INFO odoo_logistic odoo.modules.loading: Modules loaded.
2018-01-13 09:08:03,410 1 INFO odoo_logistic odoo.addons.base.module.module: getting next ir.actions.todo()
2018-01-13 09:08:03,411 1 INFO odoo_logistic odoo.addons.base.module.module: next action is ir.actions.todo(1,)
2018-01-13 09:08:03,436 1 INFO odoo_logistic werkzeug: 192.168.177.1 - - [13/Jan/2018 09:08:03] "POST /web/dataset/call_button HTTP/1.1" 200 -
2018-01-13 09:08:03,462 1 INFO odoo_logistic odoo.addons.base.ir.ir_http: Generating routing map
2018-01-13 09:08:04,093 1 INFO odoo_logistic odoo.addons.base.ir.ir_attachment: _read_file reading /var/lib/odoo/filestore/odoo_logistic/bd/bd402be51199b5dbe8b8019aaa197ff08384cf31
Traceback (most recent call last):
  File "/usr/lib/python3/dist-packages/odoo/tools/cache.py", line 84, in lookup
    r = d[key]
  File "/usr/lib/python3/dist-packages/odoo/tools/func.py", line 68, in wrapper
    return func(self, *args, **kwargs)
  File "/usr/lib/python3/dist-packages/odoo/tools/lru.py", line 44, in __getitem__
    a = self.d[obj].me
KeyError: ('ir.ui.menu', <function IrUiMenu.load_menus_root at 0x7f29b4125378>, 1, ('en_US',))

During handling of the above exception, another exception occurred:

Traceback (most recent call last):
  File "/usr/lib/python3/dist-packages/odoo/fields.py", line 944, in __get__
    value = record.env.cache.get(record, self)
  File "/usr/lib/python3/dist-packages/odoo/api.py", line 960, in get
    value = self._data[field][record.id][key]
KeyError: <odoo.api.Environment object at 0x7f29aede6518>

During handling of the above exception, another exception occurred:

Traceback (most recent call last):
  File "/usr/lib/python3/dist-packages/odoo/addons/base/ir/ir_attachment.py", line 100, in _file_read
    r = base64.b64encode(open(full_path,'rb').read())
FileNotFoundError: [Errno 2] No such file or directory: '/var/lib/odoo/filestore/odoo_logistic/bd/bd402be51199b5dbe8b8019aaa197ff08384cf31'
2018-01-13 09:08:04,093 1 INFO odoo_logistic odoo.addons.base.ir.ir_attachment: _read_file reading /var/lib/odoo/filestore/odoo_logistic/9c/9c47efe86d2251992fa7a68a4e8a206f33e5949d
Traceback (most recent call last):
  File "/usr/lib/python3/dist-packages/odoo/tools/cache.py", line 84, in lookup
    r = d[key]
  File "/usr/lib/python3/dist-packages/odoo/tools/func.py", line 68, in wrapper
    return func(self, *args, **kwargs)
  File "/usr/lib/python3/dist-packages/odoo/tools/lru.py", line 44, in __getitem__
    a = self.d[obj].me
KeyError: ('ir.ui.menu', <function IrUiMenu.load_menus_root at 0x7f29b4125378>, 1, ('en_US',))

During handling of the above exception, another exception occurred:

Traceback (most recent call last):
  File "/usr/lib/python3/dist-packages/odoo/fields.py", line 944, in __get__
    value = record.env.cache.get(record, self)
  File "/usr/lib/python3/dist-packages/odoo/api.py", line 960, in get
    value = self._data[field][record.id][key]
KeyError: <odoo.api.Environment object at 0x7f29aede6518>

During handling of the above exception, another exception occurred:

Traceback (most recent call last):
  File "/usr/lib/python3/dist-packages/odoo/addons/base/ir/ir_attachment.py", line 100, in _file_read
    r = base64.b64encode(open(full_path,'rb').read())
FileNotFoundError: [Errno 2] No such file or directory: '/var/lib/odoo/filestore/odoo_logistic/9c/9c47efe86d2251992fa7a68a4e8a206f33e5949d'
2018-01-13 09:08:09,214 1 INFO odoo_logistic odoo.models.unlink: User #1 deleted ir.attachment records with IDs: [358]
2018-01-13 09:08:10,939 1 INFO odoo_logistic odoo.models.unlink: User #1 deleted ir.attachment records with IDs: [360]
2018-01-13 09:08:11,636 1 INFO odoo_logistic werkzeug: 192.168.177.1 - - [13/Jan/2018 09:08:11] "GET /?debug=1 HTTP/1.1" 200 -
2018-01-13 09:08:11,759 1 INFO odoo_logistic werkzeug: 192.168.177.1 - - [13/Jan/2018 09:08:11] "GET /web/content/436-03967ef/web.assets_common.0.css HTTP/1.1" 200 -
2018-01-13 09:08:11,822 1 INFO odoo_logistic werkzeug: 192.168.177.1 - - [13/Jan/2018 09:08:11] "GET /web/content/441-663d39a/web.assets_frontend.0.css HTTP/1.1" 200 -
2018-01-13 09:08:11,834 1 INFO odoo_logistic werkzeug: 192.168.177.1 - - [13/Jan/2018 09:08:11] "GET /web/content/442-663d39a/web.assets_frontend.1.css HTTP/1.1" 200 -
2018-01-13 09:08:11,846 1 INFO odoo_logistic werkzeug: 192.168.177.1 - - [13/Jan/2018 09:08:11] "GET /web/content/443-a27b1f9/website.assets_editor.0.css HTTP/1.1" 200 -
2018-01-13 09:08:11,942 1 INFO odoo_logistic werkzeug: 192.168.177.1 - - [13/Jan/2018 09:08:11] "GET /web/content/444-663d39a/web.assets_frontend.js HTTP/1.1" 200 -
2018-01-13 09:08:11,954 1 INFO odoo_logistic werkzeug: 192.168.177.1 - - [13/Jan/2018 09:08:11] "GET /web/content/445-a27b1f9/website.assets_editor.js HTTP/1.1" 200 -
2018-01-13 09:08:11,962 1 INFO odoo_logistic werkzeug: 192.168.177.1 - - [13/Jan/2018 09:08:11] "GET /web/content/439-03967ef/web.assets_common.js HTTP/1.1" 304 -
2018-01-13 09:08:12,671 1 INFO odoo_logistic werkzeug: 192.168.177.1 - - [13/Jan/2018 09:08:12] "POST /web/dataset/call HTTP/1.1" 200 -
2018-01-13 09:08:12,682 1 INFO odoo_logistic werkzeug: 192.168.177.1 - - [13/Jan/2018 09:08:12] "POST /website/translations HTTP/1.1" 200 -
2018-01-13 09:08:12,712 1 INFO odoo_logistic werkzeug: 192.168.177.1 - - [13/Jan/2018 09:08:12] "POST /web/dataset/call_kw/web_tour.tour/get_consumed_tours HTTP/1.1" 200 -
2018-01-13 09:08:12,724 1 INFO ? werkzeug: 192.168.177.1 - - [13/Jan/2018 09:08:12] "GET /website/static/src/xml/website.xml?debug=1515834491748 HTTP/1.1" 200 -
2018-01-13 09:08:12,758 1 INFO ? werkzeug: 192.168.177.1 - - [13/Jan/2018 09:08:12] "GET /website/static/src/xml/website.editor.xml?debug=1515834491781 HTTP/1.1" 200 -
2018-01-13 09:08:12,778 1 INFO ? werkzeug: 192.168.177.1 - - [13/Jan/2018 09:08:12] "GET /web_editor/static/src/xml/editor.xml?debug=1515834491814 HTTP/1.1" 200 -
2018-01-13 09:08:12,795 1 INFO ? werkzeug: 192.168.177.1 - - [13/Jan/2018 09:08:12] "GET /web_planner/static/src/xml/web_planner.xml?debug=1515834491841 HTTP/1.1" 200 -
2018-01-13 09:08:12,853 1 INFO ? werkzeug: 192.168.177.1 - - [13/Jan/2018 09:08:12] "GET /web_tour/static/src/xml/tip.xml?debug=1515834491859 HTTP/1.1" 200 -
2018-01-13 09:08:12,890 1 INFO odoo_logistic werkzeug: 192.168.177.1 - - [13/Jan/2018 09:08:12] "POST /web/dataset/call_kw/web.planner/search_read HTTP/1.1" 200 -
2018-01-13 09:08:22,733 1 INFO odoo_logistic odoo.addons.base.ir.ir_attachment: _read_file reading /var/lib/odoo/filestore/odoo_logistic/bd/bd402be51199b5dbe8b8019aaa197ff08384cf31
Traceback (most recent call last):
  File "/usr/lib/python3/dist-packages/odoo/tools/cache.py", line 84, in lookup
    r = d[key]
  File "/usr/lib/python3/dist-packages/odoo/tools/func.py", line 68, in wrapper
    return func(self, *args, **kwargs)
  File "/usr/lib/python3/dist-packages/odoo/tools/lru.py", line 44, in __getitem__
    a = self.d[obj].me
KeyError: ('ir.ui.menu', <function IrUiMenu.load_menus_root at 0x7f29b4125378>, 1, ('en_US',))

During handling of the above exception, another exception occurred:

Traceback (most recent call last):
  File "/usr/lib/python3/dist-packages/odoo/fields.py", line 944, in __get__
    value = record.env.cache.get(record, self)
  File "/usr/lib/python3/dist-packages/odoo/api.py", line 960, in get
    value = self._data[field][record.id][key]
KeyError: <odoo.api.Environment object at 0x7f29ad5835c0>

During handling of the above exception, another exception occurred:

Traceback (most recent call last):
  File "/usr/lib/python3/dist-packages/odoo/addons/base/ir/ir_attachment.py", line 100, in _file_read
    r = base64.b64encode(open(full_path,'rb').read())
FileNotFoundError: [Errno 2] No such file or directory: '/var/lib/odoo/filestore/odoo_logistic/bd/bd402be51199b5dbe8b8019aaa197ff08384cf31'
2018-01-13 09:08:22,745 1 INFO odoo_logistic odoo.addons.base.ir.ir_attachment: _read_file reading /var/lib/odoo/filestore/odoo_logistic/9c/9c47efe86d2251992fa7a68a4e8a206f33e5949d
Traceback (most recent call last):
  File "/usr/lib/python3/dist-packages/odoo/tools/cache.py", line 84, in lookup
    r = d[key]
  File "/usr/lib/python3/dist-packages/odoo/tools/func.py", line 68, in wrapper
    return func(self, *args, **kwargs)
  File "/usr/lib/python3/dist-packages/odoo/tools/lru.py", line 44, in __getitem__
    a = self.d[obj].me
KeyError: ('ir.ui.menu', <function IrUiMenu.load_menus_root at 0x7f29b4125378>, 1, ('en_US',))

During handling of the above exception, another exception occurred:

Traceback (most recent call last):
  File "/usr/lib/python3/dist-packages/odoo/fields.py", line 944, in __get__
    value = record.env.cache.get(record, self)
  File "/usr/lib/python3/dist-packages/odoo/api.py", line 960, in get
    value = self._data[field][record.id][key]
KeyError: <odoo.api.Environment object at 0x7f29ad5835c0>

During handling of the above exception, another exception occurred:

Traceback (most recent call last):
  File "/usr/lib/python3/dist-packages/odoo/addons/base/ir/ir_attachment.py", line 100, in _file_read
    r = base64.b64encode(open(full_path,'rb').read())
FileNotFoundError: [Errno 2] No such file or directory: '/var/lib/odoo/filestore/odoo_logistic/9c/9c47efe86d2251992fa7a68a4e8a206f33e5949d'
2018-01-13 09:08:24,346 1 INFO odoo_logistic werkzeug: 192.168.177.1 - - [13/Jan/2018 09:08:24] "POST /website/snippets HTTP/1.1" 200 -
2018-01-13 09:08:24,479 1 INFO odoo_logistic werkzeug: 192.168.177.1 - - [13/Jan/2018 09:08:24] "GET /web/image/website.s_cover_default_image HTTP/1.1" 301 -
2018-01-13 09:08:24,482 1 INFO ? werkzeug: 192.168.177.1 - - [13/Jan/2018 09:08:24] "GET /website/static/src/img/blocks/block_title.png HTTP/1.1" 200 -
2018-01-13 09:08:24,487 1 INFO ? werkzeug: 192.168.177.1 - - [13/Jan/2018 09:08:24] "GET /website/static/src/img/blocks/block_banner.png HTTP/1.1" 200 -
2018-01-13 09:08:24,498 1 INFO ? werkzeug: 192.168.177.1 - - [13/Jan/2018 09:08:24] "GET /website/static/src/img/blocks/block_text_image.png HTTP/1.1" 200 -
2018-01-13 09:08:24,505 1 INFO ? werkzeug: 192.168.177.1 - - [13/Jan/2018 09:08:24] "GET /website/static/src/img/blocks/block_jumbotron.png HTTP/1.1" 200 -
2018-01-13 09:08:24,509 1 INFO ? werkzeug: 192.168.177.1 - - [13/Jan/2018 09:08:24] "GET /website/static/src/img/blocks/block_image_text.png HTTP/1.1" 200 -
2018-01-13 09:08:24,566 1 INFO ? werkzeug: 192.168.177.1 - - [13/Jan/2018 09:08:24] "GET /website/static/src/img/blocks/block_text_block.png HTTP/1.1" 200 -
2018-01-13 09:08:24,591 1 INFO ? werkzeug: 192.168.177.1 - - [13/Jan/2018 09:08:24] "GET /website/static/src/img/blocks/block_features.png HTTP/1.1" 200 -
2018-01-13 09:08:24,609 1 INFO ? werkzeug: 192.168.177.1 - - [13/Jan/2018 09:08:24] "GET /website/static/src/img/blocks/block_big_picture.png HTTP/1.1" 200 -
2018-01-13 09:08:24,646 1 INFO ? werkzeug: 192.168.177.1 - - [13/Jan/2018 09:08:24] "GET /website/static/src/img/blocks/block_three_columns.png HTTP/1.1" 200 -
2018-01-13 09:08:24,726 1 INFO ? werkzeug: 192.168.177.1 - - [13/Jan/2018 09:08:24] "GET /website/static/src/img/blocks/block_slider.png HTTP/1.1" 200 -
2018-01-13 09:08:24,849 1 INFO ? werkzeug: 192.168.177.1 - - [13/Jan/2018 09:08:24] "GET /website/static/src/img/blocks/block_comparison.png HTTP/1.1" 200 -
2018-01-13 09:08:24,869 1 INFO ? werkzeug: 192.168.177.1 - - [13/Jan/2018 09:08:24] "GET /website/static/src/img/blocks/block_image_gallery.png HTTP/1.1" 200 -
2018-01-13 09:08:24,910 1 INFO odoo_logistic werkzeug: 192.168.177.1 - - [13/Jan/2018 09:08:24] "GET /web/image/website.s_background_image_01 HTTP/1.1" 200 -
2018-01-13 09:08:24,935 1 INFO ? werkzeug: 192.168.177.1 - - [13/Jan/2018 09:08:24] "GET /website/static/src/img/blocks/block_button.png HTTP/1.1" 200 -
2018-01-13 09:08:24,941 1 INFO ? werkzeug: 192.168.177.1 - - [13/Jan/2018 09:08:24] "GET /website/static/src/img/blocks/block_company_team.png HTTP/1.1" 200 -
2018-01-13 09:08:24,958 1 INFO ? werkzeug: 192.168.177.1 - - [13/Jan/2018 09:08:24] "GET /website/static/src/img/blocks/block_references.png HTTP/1.1" 200 -
2018-01-13 09:08:24,968 1 INFO ? werkzeug: 192.168.177.1 - - [13/Jan/2018 09:08:24] "GET /website/static/src/img/blocks/block_faq.png HTTP/1.1" 200 -
2018-01-13 09:08:24,973 1 INFO ? werkzeug: 192.168.177.1 - - [13/Jan/2018 09:08:24] "GET /website/static/src/img/blocks/block_feature_grid.png HTTP/1.1" 200 -
2018-01-13 09:08:24,981 1 INFO odoo_logistic werkzeug: 192.168.177.1 - - [13/Jan/2018 09:08:24] "GET /web/image/website.s_background_image_03 HTTP/1.1" 200 -
2018-01-13 09:08:24,994 1 INFO ? werkzeug: 192.168.177.1 - - [13/Jan/2018 09:08:24] "GET /website/static/src/img/blocks/twitter_scroll.png HTTP/1.1" 200 -
2018-01-13 09:08:25,010 1 INFO ? werkzeug: 192.168.177.1 - - [13/Jan/2018 09:08:25] "GET /website/static/src/img/blocks/block_parallax.png HTTP/1.1" 200 -
2018-01-13 09:08:25,027 1 INFO ? werkzeug: 192.168.177.1 - - [13/Jan/2018 09:08:25] "GET /website/static/src/img/blocks/block_quotes_slider.png HTTP/1.1" 200 -
2018-01-13 09:08:25,046 1 INFO ? werkzeug: 192.168.177.1 - - [13/Jan/2018 09:08:25] "GET /website/static/src/img/blocks/block_well.png HTTP/1.1" 200 -
2018-01-13 09:08:25,074 1 INFO ? werkzeug: 192.168.177.1 - - [13/Jan/2018 09:08:25] "GET /website/static/src/img/blocks/block_panel.png HTTP/1.1" 200 -
2018-01-13 09:08:25,082 1 INFO ? werkzeug: 192.168.177.1 - - [13/Jan/2018 09:08:25] "GET /website/static/src/img/blocks/block_share.png HTTP/1.1" 200 -
2018-01-13 09:08:25,092 1 INFO odoo_logistic werkzeug: 192.168.177.1 - - [13/Jan/2018 09:08:25] "GET /web/image/website.s_background_image_04 HTTP/1.1" 200 -
2018-01-13 09:08:25,104 1 INFO ? werkzeug: 192.168.177.1 - - [13/Jan/2018 09:08:25] "GET /website/static/src/img/blocks/block_local_event.png HTTP/1.1" 200 -
2018-01-13 09:08:25,115 1 INFO ? werkzeug: 192.168.177.1 - - [13/Jan/2018 09:08:25] "GET /website/static/src/img/blocks/newsletter_subscribe_form.png HTTP/1.1" 200 -
2018-01-13 09:08:25,142 1 INFO ? werkzeug: 192.168.177.1 - - [13/Jan/2018 09:08:25] "GET /website/static/src/img/blocks/button_channel_subscribe.png HTTP/1.1" 200 -
2018-01-13 09:08:25,146 1 INFO odoo_logistic werkzeug: 192.168.177.1 - - [13/Jan/2018 09:08:25] "GET /web/image/website.s_parallax_slider_default_image HTTP/1.1" 200 -
2018-01-13 09:08:25,279 1 INFO odoo_logistic werkzeug: 192.168.177.1 - - [13/Jan/2018 09:08:25] "GET /web/image/website.s_text_image_default_image HTTP/1.1" 200 -
2018-01-13 09:08:25,283 1 INFO odoo_logistic werkzeug: 192.168.177.1 - - [13/Jan/2018 09:08:25] "GET /web/image/website.s_image_text_default_image HTTP/1.1" 200 -
2018-01-13 09:08:25,346 1 INFO odoo_logistic werkzeug: 192.168.177.1 - - [13/Jan/2018 09:08:25] "GET /web/image/website.s_big_picture_default_image HTTP/1.1" 200 -
2018-01-13 09:08:25,354 1 INFO odoo_logistic werkzeug: 192.168.177.1 - - [13/Jan/2018 09:08:25] "GET /web/image/website.library_image_11 HTTP/1.1" 200 -
2018-01-13 09:08:25,419 1 INFO odoo_logistic werkzeug: 192.168.177.1 - - [13/Jan/2018 09:08:25] "GET /web/image/website.library_image_07 HTTP/1.1" 200 -
2018-01-13 09:08:25,467 1 INFO odoo_logistic werkzeug: 192.168.177.1 - - [13/Jan/2018 09:08:25] "GET /web/image/website.library_image_13 HTTP/1.1" 200 -
2018-01-13 09:08:25,537 1 INFO odoo_logistic werkzeug: 192.168.177.1 - - [13/Jan/2018 09:08:25] "GET /web/image/website.s_company_team_image_1 HTTP/1.1" 200 -
2018-01-13 09:08:25,546 1 INFO odoo_logistic werkzeug: 192.168.177.1 - - [13/Jan/2018 09:08:25] "GET /web/image/website.s_banner_default_image HTTP/1.1" 200 -
2018-01-13 09:08:25,669 1 INFO odoo_logistic werkzeug: 192.168.177.1 - - [13/Jan/2018 09:08:25] "GET /web/image/website.s_company_team_image_4 HTTP/1.1" 200 -
2018-01-13 09:08:25,674 1 INFO odoo_logistic werkzeug: 192.168.177.1 - - [13/Jan/2018 09:08:25] "GET /web/image/website.s_company_team_image_3 HTTP/1.1" 200 -
2018-01-13 09:08:25,747 1 INFO odoo_logistic werkzeug: 192.168.177.1 - - [13/Jan/2018 09:08:25] "GET /web/image/website.s_company_team_image_2 HTTP/1.1" 200 -
2018-01-13 09:08:25,757 1 INFO odoo_logistic werkzeug: 192.168.177.1 - - [13/Jan/2018 09:08:25] "GET /web/image/website.s_reference_demo_image_2 HTTP/1.1" 200 -
2018-01-13 09:08:25,760 1 INFO odoo_logistic werkzeug: 192.168.177.1 - - [13/Jan/2018 09:08:25] "GET /web/image/website.s_reference_demo_image_1 HTTP/1.1" 200 -
2018-01-13 09:08:25,767 1 INFO odoo_logistic werkzeug: 192.168.177.1 - - [13/Jan/2018 09:08:25] "GET /web/image/website.s_reference_demo_image_3 HTTP/1.1" 200 -
2018-01-13 09:08:25,809 1 INFO odoo_logistic werkzeug: 192.168.177.1 - - [13/Jan/2018 09:08:25] "GET /web/image/website.s_reference_demo_image_4 HTTP/1.1" 200 -
2018-01-13 09:08:25,817 1 INFO odoo_logistic werkzeug: 192.168.177.1 - - [13/Jan/2018 09:08:25] "GET /web/image/website.s_reference_demo_image_5 HTTP/1.1" 200 -
2018-01-13 09:08:25,855 1 INFO odoo_logistic werkzeug: 192.168.177.1 - - [13/Jan/2018 09:08:25] "GET /web/image/website.s_image_floating_default_image HTTP/1.1" 200 -
2018-01-13 09:08:28,375 1 INFO odoo_logistic werkzeug: 192.168.177.1 - - [13/Jan/2018 09:08:28] "POST /longpolling/poll HTTP/1.1" 200 -
2018-01-13 09:08:34,928 1 INFO ? werkzeug: 192.168.177.1 - - [13/Jan/2018 09:08:34] "GET /web_editor/static/src/xml/snippets.xml?debug=1515834514005 HTTP/1.1" 200 -
2018-01-13 09:08:42,116 1 INFO ? werkzeug: 192.168.177.1 - - [13/Jan/2018 09:08:42] "GET /web/static/src/xml/dialog.xml?debug=1515834521162 HTTP/1.1" 200 -
2018-01-13 09:08:44,750 1 INFO odoo_logistic werkzeug: 192.168.177.1 - - [13/Jan/2018 09:08:44] "GET /?debug=1 HTTP/1.1" 200 -
2018-01-13 09:08:45,287 1 INFO odoo_logistic werkzeug: 192.168.177.1 - - [13/Jan/2018 09:08:45] "GET /web/content/436-03967ef/web.assets_common.0.css HTTP/1.1" 200 -
2018-01-13 09:08:45,334 1 INFO odoo_logistic werkzeug: 192.168.177.1 - - [13/Jan/2018 09:08:45] "GET /web/content/442-663d39a/web.assets_frontend.1.css HTTP/1.1" 200 -
2018-01-13 09:08:45,335 1 INFO odoo_logistic werkzeug: 192.168.177.1 - - [13/Jan/2018 09:08:45] "GET /web/content/441-663d39a/web.assets_frontend.0.css HTTP/1.1" 200 -
2018-01-13 09:08:45,388 1 INFO odoo_logistic werkzeug: 192.168.177.1 - - [13/Jan/2018 09:08:45] "GET /web/content/443-a27b1f9/website.assets_editor.0.css HTTP/1.1" 200 -
2018-01-13 09:08:45,442 1 INFO odoo_logistic werkzeug: 192.168.177.1 - - [13/Jan/2018 09:08:45] "GET /web/content/444-663d39a/web.assets_frontend.js HTTP/1.1" 304 -
2018-01-13 09:08:45,443 1 INFO odoo_logistic werkzeug: 192.168.177.1 - - [13/Jan/2018 09:08:45] "GET /web/content/445-a27b1f9/website.assets_editor.js HTTP/1.1" 304 -
2018-01-13 09:08:45,456 1 INFO odoo_logistic werkzeug: 192.168.177.1 - - [13/Jan/2018 09:08:45] "GET /web/content/439-03967ef/web.assets_common.js HTTP/1.1" 304 -
2018-01-13 09:08:45,692 1 INFO odoo_logistic werkzeug: 192.168.177.1 - - [13/Jan/2018 09:08:45] "POST /website/translations HTTP/1.1" 200 -
2018-01-13 09:08:45,700 1 INFO odoo_logistic werkzeug: 192.168.177.1 - - [13/Jan/2018 09:08:45] "POST /web/dataset/call HTTP/1.1" 200 -
2018-01-13 09:08:45,714 1 INFO odoo_logistic werkzeug: 192.168.177.1 - - [13/Jan/2018 09:08:45] "POST /web/dataset/call_kw/web_tour.tour/get_consumed_tours HTTP/1.1" 200 -
2018-01-13 09:08:45,720 1 INFO ? werkzeug: 192.168.177.1 - - [13/Jan/2018 09:08:45] "GET /website/static/src/xml/website.xml?debug=1515834524812 HTTP/1.1" 200 -
2018-01-13 09:08:45,731 1 INFO ? werkzeug: 192.168.177.1 - - [13/Jan/2018 09:08:45] "GET /website/static/src/xml/website.editor.xml?debug=1515834524830 HTTP/1.1" 200 -
2018-01-13 09:08:45,740 1 INFO ? werkzeug: 192.168.177.1 - - [13/Jan/2018 09:08:45] "GET /web_editor/static/src/xml/editor.xml?debug=1515834524841 HTTP/1.1" 200 -
2018-01-13 09:08:45,772 1 INFO ? werkzeug: 192.168.177.1 - - [13/Jan/2018 09:08:45] "GET /web_planner/static/src/xml/web_planner.xml?debug=1515834524872 HTTP/1.1" 200 -
2018-01-13 09:08:45,795 1 INFO ? werkzeug: 192.168.177.1 - - [13/Jan/2018 09:08:45] "GET /web_tour/static/src/xml/tip.xml?debug=1515834524890 HTTP/1.1" 200 -
2018-01-13 09:08:45,841 1 INFO odoo_logistic werkzeug: 192.168.177.1 - - [13/Jan/2018 09:08:45] "POST /web/dataset/call_kw/web.planner/search_read HTTP/1.1" 200 -
2018-01-13 09:08:49,443 1 INFO odoo_logistic werkzeug: 192.168.177.1 - - [13/Jan/2018 09:08:49] "GET /web/content/436-03967ef/web.assets_common.0.css HTTP/1.1" 200 -
2018-01-13 09:08:49,503 1 INFO odoo_logistic werkzeug: 192.168.177.1 - - [13/Jan/2018 09:08:49] "GET /web/content/443-a27b1f9/website.assets_editor.0.css HTTP/1.1" 200 -
2018-01-13 09:08:49,538 1 INFO odoo_logistic werkzeug: 192.168.177.1 - - [13/Jan/2018 09:08:49] "GET /web/content/442-663d39a/web.assets_frontend.1.css HTTP/1.1" 200 -
2018-01-13 09:08:49,550 1 INFO odoo_logistic werkzeug: 192.168.177.1 - - [13/Jan/2018 09:08:49] "GET /web/content/441-663d39a/web.assets_frontend.0.css HTTP/1.1" 200 -
2018-01-13 09:10:26,178 1 INFO odoo_logistic odoo.addons.base.ir.ir_attachment: _read_file reading /var/lib/odoo/filestore/odoo_logistic/bd/bd402be51199b5dbe8b8019aaa197ff08384cf31
Traceback (most recent call last):
  File "/usr/lib/python3/dist-packages/odoo/tools/cache.py", line 84, in lookup
    r = d[key]
  File "/usr/lib/python3/dist-packages/odoo/tools/func.py", line 68, in wrapper
    return func(self, *args, **kwargs)
  File "/usr/lib/python3/dist-packages/odoo/tools/lru.py", line 44, in __getitem__
    a = self.d[obj].me
KeyError: ('ir.ui.menu', <function IrUiMenu.load_menus at 0x7f29b4125598>, 1, True, ('en_US',))

During handling of the above exception, another exception occurred:

Traceback (most recent call last):
  File "/usr/lib/python3/dist-packages/odoo/fields.py", line 944, in __get__
    value = record.env.cache.get(record, self)
  File "/usr/lib/python3/dist-packages/odoo/api.py", line 960, in get
    value = self._data[field][record.id][key]
KeyError: <odoo.api.Environment object at 0x7f29ad603eb8>

During handling of the above exception, another exception occurred:

Traceback (most recent call last):
  File "/usr/lib/python3/dist-packages/odoo/addons/base/ir/ir_attachment.py", line 100, in _file_read
    r = base64.b64encode(open(full_path,'rb').read())
FileNotFoundError: [Errno 2] No such file or directory: '/var/lib/odoo/filestore/odoo_logistic/bd/bd402be51199b5dbe8b8019aaa197ff08384cf31'
2018-01-13 09:10:26,179 1 INFO odoo_logistic odoo.addons.base.ir.ir_attachment: _read_file reading /var/lib/odoo/filestore/odoo_logistic/9c/9c47efe86d2251992fa7a68a4e8a206f33e5949d
Traceback (most recent call last):
  File "/usr/lib/python3/dist-packages/odoo/tools/cache.py", line 84, in lookup
    r = d[key]
  File "/usr/lib/python3/dist-packages/odoo/tools/func.py", line 68, in wrapper
    return func(self, *args, **kwargs)
  File "/usr/lib/python3/dist-packages/odoo/tools/lru.py", line 44, in __getitem__
    a = self.d[obj].me
KeyError: ('ir.ui.menu', <function IrUiMenu.load_menus at 0x7f29b4125598>, 1, True, ('en_US',))

During handling of the above exception, another exception occurred:

Traceback (most recent call last):
  File "/usr/lib/python3/dist-packages/odoo/fields.py", line 944, in __get__
    value = record.env.cache.get(record, self)
  File "/usr/lib/python3/dist-packages/odoo/api.py", line 960, in get
    value = self._data[field][record.id][key]
KeyError: <odoo.api.Environment object at 0x7f29ad603eb8>

During handling of the above exception, another exception occurred:

Traceback (most recent call last):
  File "/usr/lib/python3/dist-packages/odoo/addons/base/ir/ir_attachment.py", line 100, in _file_read
    r = base64.b64encode(open(full_path,'rb').read())
FileNotFoundError: [Errno 2] No such file or directory: '/var/lib/odoo/filestore/odoo_logistic/9c/9c47efe86d2251992fa7a68a4e8a206f33e5949d'
2018-01-13 09:10:34,764 1 INFO ? werkzeug: 192.168.177.1 - - [13/Jan/2018 09:10:34] "GET /web/static/src/xml/dialog.xml?debug=1515834633679 HTTP/1.1" 200 -
2018-01-13 09:10:34,880 1 INFO ? werkzeug: 192.168.177.1 - - [13/Jan/2018 09:10:34] "GET /website/static/src/xml/website.contentMenu.xml?debug=1515834633796 HTTP/1.1" 200 -
2018-01-13 09:10:34,944 1 INFO odoo_logistic werkzeug: 192.168.177.1 - - [13/Jan/2018 09:10:34] "POST /web/dataset/call_kw/website.menu/get_tree HTTP/1.1" 200 -
2018-01-13 09:10:41,387 1 INFO odoo_logistic odoo.models.unlink: User #1 deleted ir.attachment records with IDs: [438, 437]
2018-01-13 09:10:51,476 1 INFO odoo_logistic odoo.models.unlink: User #1 deleted ir.attachment records with IDs: [440]
2018-01-13 09:10:52,585 1 ERROR odoo_logistic odoo.sql_db: bad query: b'DELETE FROM ir_attachment WHERE id IN (438, 437)'
ERROR: could not serialize access due to concurrent update

2018-01-13 09:10:52,586 1 ERROR odoo_logistic odoo.sql_db: bad query: b'DELETE FROM ir_attachment WHERE id IN (438, 437)'
ERROR: could not serialize access due to concurrent update

2018-01-13 09:10:52,613 1 ERROR odoo_logistic odoo.sql_db: bad query: b'SELECT "res_users"."id" as "id" FROM "res_users" WHERE "res_users".id IN (1)'
ERROR: current transaction is aborted, commands ignored until end of transaction block

2018-01-13 09:10:52,614 1 ERROR odoo_logistic odoo.sql_db: bad query: b'SELECT "res_users"."id" as "id" FROM "res_users" WHERE "res_users".id IN (1)'
ERROR: current transaction is aborted, commands ignored until end of transaction block

2018-01-13 09:10:52,615 1 INFO odoo_logistic werkzeug: 192.168.177.1 - - [13/Jan/2018 09:10:52] "GET /web?&debug= HTTP/1.1" 200 -
2018-01-13 09:10:53,295 1 ERROR odoo_logistic odoo.sql_db: bad query: b'DELETE FROM ir_attachment WHERE id IN (438, 437)'
ERROR: could not serialize access due to concurrent update

2018-01-13 09:10:53,296 1 ERROR odoo_logistic odoo.sql_db: bad query: b'SELECT "res_users"."id" as "id" FROM "res_users" WHERE "res_users".id IN (1)'
ERROR: current transaction is aborted, commands ignored until end of transaction block

2018-01-13 09:10:53,665 1 INFO odoo_logistic werkzeug: 192.168.177.1 - - [13/Jan/2018 09:10:53] "GET /web?&debug= HTTP/1.1" 500 -
2018-01-13 09:10:53,668 1 INFO odoo_logistic werkzeug: 192.168.177.1 - - [13/Jan/2018 09:10:53] "GET /web?&debug= HTTP/1.1" 500 -
2018-01-13 09:10:53,682 1 INFO odoo_logistic werkzeug: 192.168.177.1 - - [13/Jan/2018 09:10:53] "GET /web?&debug= HTTP/1.1" 500 -
2018-01-13 09:10:53,968 1 ERROR odoo_logistic werkzeug: Error on request:
Traceback (most recent call last):
  File "/usr/lib/python3/dist-packages/werkzeug/serving.py", line 205, in run_wsgi
    execute(self.server.app)
  File "/usr/lib/python3/dist-packages/werkzeug/serving.py", line 193, in execute
    application_iter = app(environ, start_response)
  File "/usr/lib/python3/dist-packages/odoo/service/server.py", line 254, in app
    return self.app(e, s)
  File "/usr/lib/python3/dist-packages/odoo/service/wsgi_server.py", line 166, in application
    return application_unproxied(environ, start_response)
  File "/usr/lib/python3/dist-packages/odoo/service/wsgi_server.py", line 154, in application_unproxied
    result = handler(environ, start_response)
  File "/usr/lib/python3/dist-packages/odoo/http.py", line 1298, in __call__
    return self.dispatch(environ, start_response)
  File "/usr/lib/python3/dist-packages/odoo/http.py", line 1272, in __call__
    return self.app(environ, start_wrapped)
  File "/usr/lib/python3/dist-packages/werkzeug/wsgi.py", line 599, in __call__
    return self.app(environ, start_response)
  File "/usr/lib/python3/dist-packages/odoo/http.py", line 1473, in dispatch
    result = ir_http._dispatch()
  File "/usr/lib/python3/dist-packages/odoo/addons/auth_signup/models/ir_http.py", line 19, in _dispatch
    return super(Http, cls)._dispatch()
  File "/usr/lib/python3/dist-packages/odoo/addons/web_editor/models/ir_http.py", line 21, in _dispatch
    return super(IrHttp, cls)._dispatch()
  File "/usr/lib/python3/dist-packages/odoo/addons/http_routing/models/ir_http.py", line 397, in _dispatch
    result = super(IrHttp, cls)._dispatch()
  File "/usr/lib/python3/dist-packages/odoo/addons/base/ir/ir_http.py", line 212, in _dispatch
    return cls._handle_exception(e)
  File "/usr/lib/python3/dist-packages/odoo/addons/website/models/ir_http.py", line 160, in _handle_exception
    return super(Http, cls)._handle_exception(exception)
  File "/usr/lib/python3/dist-packages/odoo/addons/base/ir/ir_http.py", line 182, in _handle_exception
    return request._handle_exception(exception)
  File "/usr/lib/python3/dist-packages/odoo/http.py", line 761, in _handle_exception
    return super(HttpRequest, self)._handle_exception(exception)
  File "/usr/lib/python3/dist-packages/odoo/http.py", line 307, in _handle_exception
    raise pycompat.reraise(type(exception), exception, sys.exc_info()[2])
  File "/usr/lib/python3/dist-packages/odoo/tools/pycompat.py", line 87, in reraise
    raise value
  File "/usr/lib/python3/dist-packages/odoo/addons/base/ir/ir_http.py", line 208, in _dispatch
    result = request.dispatch()
  File "/usr/lib/python3/dist-packages/odoo/http.py", line 820, in dispatch
    r = self._call_function(**self.params)
  File "/usr/lib/python3/dist-packages/odoo/http.py", line 339, in _call_function
    return checked_call(self.db, *args, **kwargs)
  File "/usr/lib/python3/dist-packages/odoo/service/model.py", line 97, in wrapper
    return f(dbname, *args, **kwargs)
  File "/usr/lib/python3/dist-packages/odoo/http.py", line 335, in checked_call
    result.flatten()
  File "/usr/lib/python3/dist-packages/odoo/http.py", line 1249, in flatten
    self.response.append(self.render())
  File "/usr/lib/python3/dist-packages/odoo/http.py", line 1242, in render
    return env["ir.ui.view"].render_template(self.template, self.qcontext)
  File "/usr/lib/python3/dist-packages/odoo/addons/base/ir/ir_ui_view.py", line 1052, in render_template
    return self.browse(self.get_view_id(template)).render(values, engine)
  File "/usr/lib/python3/dist-packages/odoo/addons/website/models/ir_ui_view.py", line 113, in render
    return super(View, self).render(values, engine=engine)
  File "/usr/lib/python3/dist-packages/odoo/addons/web_editor/models/ir_ui_view.py", line 27, in render
    return super(IrUiView, self).render(values=values, engine=engine)
  File "/usr/lib/python3/dist-packages/odoo/addons/base/ir/ir_ui_view.py", line 1061, in render
    return self.env[engine].render(self.id, qcontext)
  File "/usr/lib/python3/dist-packages/odoo/addons/base/ir/ir_qweb/ir_qweb.py", line 57, in render
    return super(IrQWeb, self).render(id_or_xml_id, values=values, **context)
  File "/usr/lib/python3/dist-packages/odoo/addons/base/ir/ir_qweb/qweb.py", line 271, in render
    self.compile(template, options)(self, body.append, values or {})
  File "/usr/lib/python3/dist-packages/odoo/addons/base/ir/ir_qweb/qweb.py", line 346, in _compiled_fn
    element, document = self.get_template(template, options)
  File "/usr/lib/python3/dist-packages/odoo/addons/base/ir/ir_qweb/qweb.py", line 371, in get_template
    raise QWebException("load could not load template", name=template)
odoo.addons.base.ir.ir_qweb.qweb.QWebException: None
Traceback (most recent call last):
  File "/usr/lib/python3/dist-packages/odoo/tools/cache.py", line 84, in lookup
    r = d[key]
  File "/usr/lib/python3/dist-packages/odoo/tools/func.py", line 68, in wrapper
    return func(self, *args, **kwargs)
  File "/usr/lib/python3/dist-packages/odoo/tools/lru.py", line 44, in __getitem__
    a = self.d[obj].me
KeyError: ('ir.qweb', <function IrQWeb._get_asset at 0x7f29ae22c8c8>, 'web.assets_backend', 'en_US', True, False, True, False, (None,))

During handling of the above exception, another exception occurred:

Traceback (most recent call last):
  File "/usr/lib/python3/dist-packages/odoo/addons/base/ir/ir_qweb/qweb.py", line 341, in _compiled_fn
    return compiled(self, append, new, options, log)
  File "<template>", line 1, in template_167_390
  File "<template>", line 2, in body_call_content_389
  File "<template>", line 3, in set_384
  File "/usr/lib/python3/dist-packages/odoo/addons/website/models/ir_qweb.py", line 30, in _get_asset
    return super(QWeb, self)._get_asset(xmlid, options, css, js, debug, async, values)
  File "<decorator-gen-36>", line 2, in _get_asset
  File "/usr/lib/python3/dist-packages/odoo/tools/cache.py", line 89, in lookup
    value = d[key] = self.method(*args, **kwargs)
  File "/usr/lib/python3/dist-packages/odoo/addons/base/ir/ir_qweb/ir_qweb.py", line 197, in _get_asset
    return asset.to_html(css=css, js=js, debug=debug, async=async, url_for=(values or {}).get('url_for', lambda url: url))
  File "/usr/lib/python3/dist-packages/odoo/addons/base/ir/ir_qweb/assetsbundle.py", line 125, in to_html
    css_attachments = self.css() or []
  File "/usr/lib/python3/dist-packages/odoo/addons/base/ir/ir_qweb/assetsbundle.py", line 269, in css
    self.save_attachment("css", ' '.join(page), inc=idx)
  File "/usr/lib/python3/dist-packages/odoo/addons/base/ir/ir_qweb/assetsbundle.py", line 228, in save_attachment
    self.clean_attachments(type)
  File "/usr/lib/python3/dist-packages/odoo/addons/base/ir/ir_qweb/assetsbundle.py", line 181, in clean_attachments
    return ira.sudo().search(domain).unlink()
  File "/usr/lib/python3/dist-packages/odoo/addons/base/ir/ir_attachment.py", line 426, in unlink
    res = super(IrAttachment, self).unlink()
  File "/usr/lib/python3/dist-packages/odoo/models.py", line 2857, in unlink
    cr.execute(query, (sub_ids,))
  File "/usr/lib/python3/dist-packages/odoo/sql_db.py", line 155, in wrapper
    return f(self, *args, **kwargs)
  File "/usr/lib/python3/dist-packages/odoo/sql_db.py", line 232, in execute
    res = self._obj.execute(query, params)
psycopg2.extensions.TransactionRollbackError: could not serialize access due to concurrent update


During handling of the above exception, another exception occurred:

Traceback (most recent call last):
  File "/usr/lib/python3/dist-packages/odoo/fields.py", line 944, in __get__
    value = record.env.cache.get(record, self)
  File "/usr/lib/python3/dist-packages/odoo/api.py", line 960, in get
    value = self._data[field][record.id][key]
KeyError: <odoo.api.Environment object at 0x7f29af2d6780>

During handling of the above exception, another exception occurred:

Traceback (most recent call last):
  File "/usr/lib/python3/dist-packages/odoo/addons/base/ir/ir_qweb/qweb.py", line 367, in get_template
    document = options.get('load', self.load)(template, options)
  File "/usr/lib/python3/dist-packages/odoo/addons/base/ir/ir_qweb/ir_qweb.py", line 85, in load
    template = env['ir.ui.view'].read_template(name)
  File "/usr/lib/python3/dist-packages/odoo/addons/base/ir/ir_ui_view.py", line 947, in read_template
    return self._read_template(self.get_view_id(xml_id))
  File "<decorator-gen-25>", line 2, in _read_template
  File "/usr/lib/python3/dist-packages/odoo/tools/cache.py", line 82, in lookup
    key = key0 + self.key(*args, **kwargs)
  File "<string>", line 1, in <lambda>
  File "/usr/lib/python3/dist-packages/odoo/fields.py", line 948, in __get__
    self.determine_value(record)
  File "/usr/lib/python3/dist-packages/odoo/fields.py", line 1049, in determine_value
    record._prefetch_field(self)
  File "/usr/lib/python3/dist-packages/odoo/models.py", line 2568, in _prefetch_field
    result = records.read([f.name for f in fs], load='_classic_write')
  File "/usr/lib/python3/dist-packages/odoo/addons/base/res/res_users.py", line 865, in read
    res = super(UsersView, self).read(other_fields, load=load)
  File "/usr/lib/python3/dist-packages/odoo/addons/base/res/res_users.py", line 295, in read
    result = super(Users, self).read(fields=fields, load=load)
  File "/usr/lib/python3/dist-packages/odoo/models.py", line 2512, in read
    self._read_from_database(stored, inherited)
  File "/usr/lib/python3/dist-packages/odoo/models.py", line 2631, in _read_from_database
    cr.execute(query_str, params)
  File "/usr/lib/python3/dist-packages/odoo/sql_db.py", line 155, in wrapper
    return f(self, *args, **kwargs)
  File "/usr/lib/python3/dist-packages/odoo/sql_db.py", line 232, in execute
    res = self._obj.execute(query, params)
psycopg2.InternalError: current transaction is aborted, commands ignored until end of transaction block


load could not load template
Template: 167
2018-01-13 09:10:53,973 1 ERROR odoo_logistic werkzeug: Error on request:
Traceback (most recent call last):
  File "/usr/lib/python3/dist-packages/werkzeug/serving.py", line 205, in run_wsgi
    execute(self.server.app)
  File "/usr/lib/python3/dist-packages/werkzeug/serving.py", line 193, in execute
    application_iter = app(environ, start_response)
  File "/usr/lib/python3/dist-packages/odoo/service/server.py", line 254, in app
    return self.app(e, s)
  File "/usr/lib/python3/dist-packages/odoo/service/wsgi_server.py", line 166, in application
    return application_unproxied(environ, start_response)
  File "/usr/lib/python3/dist-packages/odoo/service/wsgi_server.py", line 154, in application_unproxied
    result = handler(environ, start_response)
  File "/usr/lib/python3/dist-packages/odoo/http.py", line 1298, in __call__
    return self.dispatch(environ, start_response)
  File "/usr/lib/python3/dist-packages/odoo/http.py", line 1272, in __call__
    return self.app(environ, start_wrapped)
  File "/usr/lib/python3/dist-packages/werkzeug/wsgi.py", line 599, in __call__
    return self.app(environ, start_response)
  File "/usr/lib/python3/dist-packages/odoo/http.py", line 1473, in dispatch
    result = ir_http._dispatch()
  File "/usr/lib/python3/dist-packages/odoo/addons/auth_signup/models/ir_http.py", line 19, in _dispatch
    return super(Http, cls)._dispatch()
  File "/usr/lib/python3/dist-packages/odoo/addons/web_editor/models/ir_http.py", line 21, in _dispatch
    return super(IrHttp, cls)._dispatch()
  File "/usr/lib/python3/dist-packages/odoo/addons/http_routing/models/ir_http.py", line 397, in _dispatch
    result = super(IrHttp, cls)._dispatch()
  File "/usr/lib/python3/dist-packages/odoo/addons/base/ir/ir_http.py", line 212, in _dispatch
    return cls._handle_exception(e)
  File "/usr/lib/python3/dist-packages/odoo/addons/website/models/ir_http.py", line 160, in _handle_exception
    return super(Http, cls)._handle_exception(exception)
  File "/usr/lib/python3/dist-packages/odoo/addons/base/ir/ir_http.py", line 182, in _handle_exception
    return request._handle_exception(exception)
  File "/usr/lib/python3/dist-packages/odoo/http.py", line 761, in _handle_exception
    return super(HttpRequest, self)._handle_exception(exception)
  File "/usr/lib/python3/dist-packages/odoo/http.py", line 307, in _handle_exception
    raise pycompat.reraise(type(exception), exception, sys.exc_info()[2])
  File "/usr/lib/python3/dist-packages/odoo/tools/pycompat.py", line 87, in reraise
    raise value
  File "/usr/lib/python3/dist-packages/odoo/addons/base/ir/ir_http.py", line 208, in _dispatch
    result = request.dispatch()
  File "/usr/lib/python3/dist-packages/odoo/http.py", line 820, in dispatch
    r = self._call_function(**self.params)
  File "/usr/lib/python3/dist-packages/odoo/http.py", line 339, in _call_function
    return checked_call(self.db, *args, **kwargs)
  File "/usr/lib/python3/dist-packages/odoo/service/model.py", line 97, in wrapper
    return f(dbname, *args, **kwargs)
  File "/usr/lib/python3/dist-packages/odoo/http.py", line 335, in checked_call
    result.flatten()
  File "/usr/lib/python3/dist-packages/odoo/http.py", line 1249, in flatten
    self.response.append(self.render())
  File "/usr/lib/python3/dist-packages/odoo/http.py", line 1242, in render
    return env["ir.ui.view"].render_template(self.template, self.qcontext)
  File "/usr/lib/python3/dist-packages/odoo/addons/base/ir/ir_ui_view.py", line 1052, in render_template
    return self.browse(self.get_view_id(template)).render(values, engine)
  File "/usr/lib/python3/dist-packages/odoo/addons/website/models/ir_ui_view.py", line 113, in render
    return super(View, self).render(values, engine=engine)
  File "/usr/lib/python3/dist-packages/odoo/addons/web_editor/models/ir_ui_view.py", line 27, in render
    return super(IrUiView, self).render(values=values, engine=engine)
  File "/usr/lib/python3/dist-packages/odoo/addons/base/ir/ir_ui_view.py", line 1061, in render
    return self.env[engine].render(self.id, qcontext)
  File "/usr/lib/python3/dist-packages/odoo/addons/base/ir/ir_qweb/ir_qweb.py", line 57, in render
    return super(IrQWeb, self).render(id_or_xml_id, values=values, **context)
  File "/usr/lib/python3/dist-packages/odoo/addons/base/ir/ir_qweb/qweb.py", line 271, in render
    self.compile(template, options)(self, body.append, values or {})
  File "/usr/lib/python3/dist-packages/odoo/addons/base/ir/ir_qweb/qweb.py", line 346, in _compiled_fn
    element, document = self.get_template(template, options)
  File "/usr/lib/python3/dist-packages/odoo/addons/base/ir/ir_qweb/qweb.py", line 371, in get_template
    raise QWebException("load could not load template", name=template)
odoo.addons.base.ir.ir_qweb.qweb.QWebException: None
Traceback (most recent call last):
  File "/usr/lib/python3/dist-packages/odoo/tools/cache.py", line 84, in lookup
    r = d[key]
  File "/usr/lib/python3/dist-packages/odoo/tools/func.py", line 68, in wrapper
    return func(self, *args, **kwargs)
  File "/usr/lib/python3/dist-packages/odoo/tools/lru.py", line 44, in __getitem__
    a = self.d[obj].me
KeyError: ('ir.qweb', <function IrQWeb._get_asset at 0x7f29ae22c8c8>, 'web.assets_backend', 'en_US', True, False, True, False, (None,))

During handling of the above exception, another exception occurred:

Traceback (most recent call last):
  File "/usr/lib/python3/dist-packages/odoo/addons/base/ir/ir_qweb/qweb.py", line 341, in _compiled_fn
    return compiled(self, append, new, options, log)
  File "<template>", line 1, in template_167_390
  File "<template>", line 2, in body_call_content_389
  File "<template>", line 3, in set_384
  File "/usr/lib/python3/dist-packages/odoo/addons/website/models/ir_qweb.py", line 30, in _get_asset
    return super(QWeb, self)._get_asset(xmlid, options, css, js, debug, async, values)
  File "<decorator-gen-36>", line 2, in _get_asset
  File "/usr/lib/python3/dist-packages/odoo/tools/cache.py", line 89, in lookup
    value = d[key] = self.method(*args, **kwargs)
  File "/usr/lib/python3/dist-packages/odoo/addons/base/ir/ir_qweb/ir_qweb.py", line 197, in _get_asset
    return asset.to_html(css=css, js=js, debug=debug, async=async, url_for=(values or {}).get('url_for', lambda url: url))
  File "/usr/lib/python3/dist-packages/odoo/addons/base/ir/ir_qweb/assetsbundle.py", line 125, in to_html
    css_attachments = self.css() or []
  File "/usr/lib/python3/dist-packages/odoo/addons/base/ir/ir_qweb/assetsbundle.py", line 269, in css
    self.save_attachment("css", ' '.join(page), inc=idx)
  File "/usr/lib/python3/dist-packages/odoo/addons/base/ir/ir_qweb/assetsbundle.py", line 228, in save_attachment
    self.clean_attachments(type)
  File "/usr/lib/python3/dist-packages/odoo/addons/base/ir/ir_qweb/assetsbundle.py", line 181, in clean_attachments
    return ira.sudo().search(domain).unlink()
  File "/usr/lib/python3/dist-packages/odoo/addons/base/ir/ir_attachment.py", line 426, in unlink
    res = super(IrAttachment, self).unlink()
  File "/usr/lib/python3/dist-packages/odoo/models.py", line 2857, in unlink
    cr.execute(query, (sub_ids,))
  File "/usr/lib/python3/dist-packages/odoo/sql_db.py", line 155, in wrapper
    return f(self, *args, **kwargs)
  File "/usr/lib/python3/dist-packages/odoo/sql_db.py", line 232, in execute
    res = self._obj.execute(query, params)
psycopg2.extensions.TransactionRollbackError: could not serialize access due to concurrent update


During handling of the above exception, another exception occurred:

Traceback (most recent call last):
  File "/usr/lib/python3/dist-packages/odoo/fields.py", line 944, in __get__
    value = record.env.cache.get(record, self)
  File "/usr/lib/python3/dist-packages/odoo/api.py", line 960, in get
    value = self._data[field][record.id][key]
KeyError: <odoo.api.Environment object at 0x7f29af446240>

During handling of the above exception, another exception occurred:

Traceback (most recent call last):
  File "/usr/lib/python3/dist-packages/odoo/addons/base/ir/ir_qweb/qweb.py", line 367, in get_template
    document = options.get('load', self.load)(template, options)
  File "/usr/lib/python3/dist-packages/odoo/addons/base/ir/ir_qweb/ir_qweb.py", line 85, in load
    template = env['ir.ui.view'].read_template(name)
  File "/usr/lib/python3/dist-packages/odoo/addons/base/ir/ir_ui_view.py", line 947, in read_template
    return self._read_template(self.get_view_id(xml_id))
  File "<decorator-gen-25>", line 2, in _read_template
  File "/usr/lib/python3/dist-packages/odoo/tools/cache.py", line 82, in lookup
    key = key0 + self.key(*args, **kwargs)
  File "<string>", line 1, in <lambda>
  File "/usr/lib/python3/dist-packages/odoo/fields.py", line 948, in __get__
    self.determine_value(record)
  File "/usr/lib/python3/dist-packages/odoo/fields.py", line 1049, in determine_value
    record._prefetch_field(self)
  File "/usr/lib/python3/dist-packages/odoo/models.py", line 2568, in _prefetch_field
    result = records.read([f.name for f in fs], load='_classic_write')
  File "/usr/lib/python3/dist-packages/odoo/addons/base/res/res_users.py", line 865, in read
    res = super(UsersView, self).read(other_fields, load=load)
  File "/usr/lib/python3/dist-packages/odoo/addons/base/res/res_users.py", line 295, in read
    result = super(Users, self).read(fields=fields, load=load)
  File "/usr/lib/python3/dist-packages/odoo/models.py", line 2512, in read
    self._read_from_database(stored, inherited)
  File "/usr/lib/python3/dist-packages/odoo/models.py", line 2631, in _read_from_database
    cr.execute(query_str, params)
  File "/usr/lib/python3/dist-packages/odoo/sql_db.py", line 155, in wrapper
    return f(self, *args, **kwargs)
  File "/usr/lib/python3/dist-packages/odoo/sql_db.py", line 232, in execute
    res = self._obj.execute(query, params)
psycopg2.InternalError: current transaction is aborted, commands ignored until end of transaction block


load could not load template
Template: 167
2018-01-13 09:10:53,978 1 ERROR odoo_logistic werkzeug: Error on request:
Traceback (most recent call last):
  File "/usr/lib/python3/dist-packages/werkzeug/serving.py", line 205, in run_wsgi
    execute(self.server.app)
  File "/usr/lib/python3/dist-packages/werkzeug/serving.py", line 193, in execute
    application_iter = app(environ, start_response)
  File "/usr/lib/python3/dist-packages/odoo/service/server.py", line 254, in app
    return self.app(e, s)
  File "/usr/lib/python3/dist-packages/odoo/service/wsgi_server.py", line 166, in application
    return application_unproxied(environ, start_response)
  File "/usr/lib/python3/dist-packages/odoo/service/wsgi_server.py", line 154, in application_unproxied
    result = handler(environ, start_response)
  File "/usr/lib/python3/dist-packages/odoo/http.py", line 1298, in __call__
    return self.dispatch(environ, start_response)
  File "/usr/lib/python3/dist-packages/odoo/http.py", line 1272, in __call__
    return self.app(environ, start_wrapped)
  File "/usr/lib/python3/dist-packages/werkzeug/wsgi.py", line 599, in __call__
    return self.app(environ, start_response)
  File "/usr/lib/python3/dist-packages/odoo/http.py", line 1473, in dispatch
    result = ir_http._dispatch()
  File "/usr/lib/python3/dist-packages/odoo/addons/auth_signup/models/ir_http.py", line 19, in _dispatch
    return super(Http, cls)._dispatch()
  File "/usr/lib/python3/dist-packages/odoo/addons/web_editor/models/ir_http.py", line 21, in _dispatch
    return super(IrHttp, cls)._dispatch()
  File "/usr/lib/python3/dist-packages/odoo/addons/http_routing/models/ir_http.py", line 397, in _dispatch
    result = super(IrHttp, cls)._dispatch()
  File "/usr/lib/python3/dist-packages/odoo/addons/base/ir/ir_http.py", line 212, in _dispatch
    return cls._handle_exception(e)
  File "/usr/lib/python3/dist-packages/odoo/addons/website/models/ir_http.py", line 160, in _handle_exception
    return super(Http, cls)._handle_exception(exception)
  File "/usr/lib/python3/dist-packages/odoo/addons/base/ir/ir_http.py", line 182, in _handle_exception
    return request._handle_exception(exception)
  File "/usr/lib/python3/dist-packages/odoo/http.py", line 761, in _handle_exception
    return super(HttpRequest, self)._handle_exception(exception)
  File "/usr/lib/python3/dist-packages/odoo/http.py", line 307, in _handle_exception
    raise pycompat.reraise(type(exception), exception, sys.exc_info()[2])
  File "/usr/lib/python3/dist-packages/odoo/tools/pycompat.py", line 87, in reraise
    raise value
  File "/usr/lib/python3/dist-packages/odoo/addons/base/ir/ir_http.py", line 208, in _dispatch
    result = request.dispatch()
  File "/usr/lib/python3/dist-packages/odoo/http.py", line 820, in dispatch
    r = self._call_function(**self.params)
  File "/usr/lib/python3/dist-packages/odoo/http.py", line 339, in _call_function
    return checked_call(self.db, *args, **kwargs)
  File "/usr/lib/python3/dist-packages/odoo/service/model.py", line 97, in wrapper
    return f(dbname, *args, **kwargs)
  File "/usr/lib/python3/dist-packages/odoo/http.py", line 335, in checked_call
    result.flatten()
  File "/usr/lib/python3/dist-packages/odoo/http.py", line 1249, in flatten
    self.response.append(self.render())
  File "/usr/lib/python3/dist-packages/odoo/http.py", line 1242, in render
    return env["ir.ui.view"].render_template(self.template, self.qcontext)
  File "/usr/lib/python3/dist-packages/odoo/addons/base/ir/ir_ui_view.py", line 1052, in render_template
    return self.browse(self.get_view_id(template)).render(values, engine)
  File "/usr/lib/python3/dist-packages/odoo/addons/website/models/ir_ui_view.py", line 113, in render
    return super(View, self).render(values, engine=engine)
  File "/usr/lib/python3/dist-packages/odoo/addons/web_editor/models/ir_ui_view.py", line 27, in render
    return super(IrUiView, self).render(values=values, engine=engine)
  File "/usr/lib/python3/dist-packages/odoo/addons/base/ir/ir_ui_view.py", line 1061, in render
    return self.env[engine].render(self.id, qcontext)
  File "/usr/lib/python3/dist-packages/odoo/addons/base/ir/ir_qweb/ir_qweb.py", line 57, in render
    return super(IrQWeb, self).render(id_or_xml_id, values=values, **context)
  File "/usr/lib/python3/dist-packages/odoo/addons/base/ir/ir_qweb/qweb.py", line 271, in render
    self.compile(template, options)(self, body.append, values or {})
  File "/usr/lib/python3/dist-packages/odoo/addons/base/ir/ir_qweb/qweb.py", line 346, in _compiled_fn
    element, document = self.get_template(template, options)
  File "/usr/lib/python3/dist-packages/odoo/addons/base/ir/ir_qweb/qweb.py", line 371, in get_template
    raise QWebException("load could not load template", name=template)
odoo.addons.base.ir.ir_qweb.qweb.QWebException: None
Traceback (most recent call last):
  File "/usr/lib/python3/dist-packages/odoo/tools/cache.py", line 84, in lookup
    r = d[key]
  File "/usr/lib/python3/dist-packages/odoo/tools/func.py", line 68, in wrapper
    return func(self, *args, **kwargs)
  File "/usr/lib/python3/dist-packages/odoo/tools/lru.py", line 44, in __getitem__
    a = self.d[obj].me
KeyError: ('ir.qweb', <function IrQWeb._get_asset at 0x7f29ae22c8c8>, 'web.assets_backend', 'en_US', True, False, True, False, (None,))

During handling of the above exception, another exception occurred:

Traceback (most recent call last):
  File "/usr/lib/python3/dist-packages/odoo/addons/base/ir/ir_qweb/qweb.py", line 341, in _compiled_fn
    return compiled(self, append, new, options, log)
  File "<template>", line 1, in template_167_390
  File "<template>", line 2, in body_call_content_389
  File "<template>", line 3, in set_384
  File "/usr/lib/python3/dist-packages/odoo/addons/website/models/ir_qweb.py", line 30, in _get_asset
    return super(QWeb, self)._get_asset(xmlid, options, css, js, debug, async, values)
  File "<decorator-gen-36>", line 2, in _get_asset
  File "/usr/lib/python3/dist-packages/odoo/tools/cache.py", line 89, in lookup
    value = d[key] = self.method(*args, **kwargs)
  File "/usr/lib/python3/dist-packages/odoo/addons/base/ir/ir_qweb/ir_qweb.py", line 197, in _get_asset
    return asset.to_html(css=css, js=js, debug=debug, async=async, url_for=(values or {}).get('url_for', lambda url: url))
  File "/usr/lib/python3/dist-packages/odoo/addons/base/ir/ir_qweb/assetsbundle.py", line 125, in to_html
    css_attachments = self.css() or []
  File "/usr/lib/python3/dist-packages/odoo/addons/base/ir/ir_qweb/assetsbundle.py", line 269, in css
    self.save_attachment("css", ' '.join(page), inc=idx)
  File "/usr/lib/python3/dist-packages/odoo/addons/base/ir/ir_qweb/assetsbundle.py", line 228, in save_attachment
    self.clean_attachments(type)
  File "/usr/lib/python3/dist-packages/odoo/addons/base/ir/ir_qweb/assetsbundle.py", line 181, in clean_attachments
    return ira.sudo().search(domain).unlink()
  File "/usr/lib/python3/dist-packages/odoo/addons/base/ir/ir_attachment.py", line 426, in unlink
    res = super(IrAttachment, self).unlink()
  File "/usr/lib/python3/dist-packages/odoo/models.py", line 2857, in unlink
    cr.execute(query, (sub_ids,))
  File "/usr/lib/python3/dist-packages/odoo/sql_db.py", line 155, in wrapper
    return f(self, *args, **kwargs)
  File "/usr/lib/python3/dist-packages/odoo/sql_db.py", line 232, in execute
    res = self._obj.execute(query, params)
psycopg2.extensions.TransactionRollbackError: could not serialize access due to concurrent update


During handling of the above exception, another exception occurred:

Traceback (most recent call last):
  File "/usr/lib/python3/dist-packages/odoo/fields.py", line 944, in __get__
    value = record.env.cache.get(record, self)
  File "/usr/lib/python3/dist-packages/odoo/api.py", line 960, in get
    value = self._data[field][record.id][key]
KeyError: <odoo.api.Environment object at 0x7f2991da6dd8>

During handling of the above exception, another exception occurred:

Traceback (most recent call last):
  File "/usr/lib/python3/dist-packages/odoo/addons/base/ir/ir_qweb/qweb.py", line 367, in get_template
    document = options.get('load', self.load)(template, options)
  File "/usr/lib/python3/dist-packages/odoo/addons/base/ir/ir_qweb/ir_qweb.py", line 85, in load
    template = env['ir.ui.view'].read_template(name)
  File "/usr/lib/python3/dist-packages/odoo/addons/base/ir/ir_ui_view.py", line 947, in read_template
    return self._read_template(self.get_view_id(xml_id))
  File "<decorator-gen-25>", line 2, in _read_template
  File "/usr/lib/python3/dist-packages/odoo/tools/cache.py", line 82, in lookup
    key = key0 + self.key(*args, **kwargs)
  File "<string>", line 1, in <lambda>
  File "/usr/lib/python3/dist-packages/odoo/fields.py", line 948, in __get__
    self.determine_value(record)
  File "/usr/lib/python3/dist-packages/odoo/fields.py", line 1049, in determine_value
    record._prefetch_field(self)
  File "/usr/lib/python3/dist-packages/odoo/models.py", line 2568, in _prefetch_field
    result = records.read([f.name for f in fs], load='_classic_write')
  File "/usr/lib/python3/dist-packages/odoo/addons/base/res/res_users.py", line 865, in read
    res = super(UsersView, self).read(other_fields, load=load)
  File "/usr/lib/python3/dist-packages/odoo/addons/base/res/res_users.py", line 295, in read
    result = super(Users, self).read(fields=fields, load=load)
  File "/usr/lib/python3/dist-packages/odoo/models.py", line 2512, in read
    self._read_from_database(stored, inherited)
  File "/usr/lib/python3/dist-packages/odoo/models.py", line 2631, in _read_from_database
    cr.execute(query_str, params)
  File "/usr/lib/python3/dist-packages/odoo/sql_db.py", line 155, in wrapper
    return f(self, *args, **kwargs)
  File "/usr/lib/python3/dist-packages/odoo/sql_db.py", line 232, in execute
    res = self._obj.execute(query, params)
psycopg2.InternalError: current transaction is aborted, commands ignored until end of transaction block


load could not load template
Template: 167
2018-01-13 09:11:00,016 1 INFO odoo_logistic odoo.addons.base.ir.ir_attachment: _read_file reading /var/lib/odoo/filestore/odoo_logistic/bd/bd402be51199b5dbe8b8019aaa197ff08384cf31
Traceback (most recent call last):
  File "/usr/lib/python3/dist-packages/odoo/tools/cache.py", line 84, in lookup
    r = d[key]
  File "/usr/lib/python3/dist-packages/odoo/tools/func.py", line 68, in wrapper
    return func(self, *args, **kwargs)
  File "/usr/lib/python3/dist-packages/odoo/tools/lru.py", line 44, in __getitem__
    a = self.d[obj].me
KeyError: ('ir.ui.menu', <function IrUiMenu.load_menus_root at 0x7f29b4125378>, 1, ('en_US',))

During handling of the above exception, another exception occurred:

Traceback (most recent call last):
  File "/usr/lib/python3/dist-packages/odoo/fields.py", line 944, in __get__
    value = record.env.cache.get(record, self)
  File "/usr/lib/python3/dist-packages/odoo/api.py", line 960, in get
    value = self._data[field][record.id][key]
KeyError: <odoo.api.Environment object at 0x7f29af134048>

During handling of the above exception, another exception occurred:

Traceback (most recent call last):
  File "/usr/lib/python3/dist-packages/odoo/addons/base/ir/ir_attachment.py", line 100, in _file_read
    r = base64.b64encode(open(full_path,'rb').read())
FileNotFoundError: [Errno 2] No such file or directory: '/var/lib/odoo/filestore/odoo_logistic/bd/bd402be51199b5dbe8b8019aaa197ff08384cf31'
2018-01-13 09:11:00,017 1 INFO odoo_logistic odoo.addons.base.ir.ir_attachment: _read_file reading /var/lib/odoo/filestore/odoo_logistic/9c/9c47efe86d2251992fa7a68a4e8a206f33e5949d
Traceback (most recent call last):
  File "/usr/lib/python3/dist-packages/odoo/tools/cache.py", line 84, in lookup
    r = d[key]
  File "/usr/lib/python3/dist-packages/odoo/tools/func.py", line 68, in wrapper
    return func(self, *args, **kwargs)
  File "/usr/lib/python3/dist-packages/odoo/tools/lru.py", line 44, in __getitem__
    a = self.d[obj].me
KeyError: ('ir.ui.menu', <function IrUiMenu.load_menus_root at 0x7f29b4125378>, 1, ('en_US',))

During handling of the above exception, another exception occurred:

Traceback (most recent call last):
  File "/usr/lib/python3/dist-packages/odoo/fields.py", line 944, in __get__
    value = record.env.cache.get(record, self)
  File "/usr/lib/python3/dist-packages/odoo/api.py", line 960, in get
    value = self._data[field][record.id][key]
KeyError: <odoo.api.Environment object at 0x7f29af134048>

During handling of the above exception, another exception occurred:

Traceback (most recent call last):
  File "/usr/lib/python3/dist-packages/odoo/addons/base/ir/ir_attachment.py", line 100, in _file_read
    r = base64.b64encode(open(full_path,'rb').read())
FileNotFoundError: [Errno 2] No such file or directory: '/var/lib/odoo/filestore/odoo_logistic/9c/9c47efe86d2251992fa7a68a4e8a206f33e5949d'
2018-01-13 09:11:01,768 1 INFO odoo_logistic werkzeug: 192.168.177.1 - - [13/Jan/2018 09:11:01] "GET / HTTP/1.1" 200 -
2018-01-13 09:11:02,101 1 INFO odoo_logistic werkzeug: 192.168.177.1 - - [13/Jan/2018 09:11:02] "GET /web/content/443-a27b1f9/website.assets_editor.0.css HTTP/1.1" 200 -
2018-01-13 09:11:02,114 1 INFO odoo_logistic werkzeug: 192.168.177.1 - - [13/Jan/2018 09:11:02] "GET /web/content/442-663d39a/web.assets_frontend.1.css HTTP/1.1" 200 -
2018-01-13 09:11:02,126 1 INFO odoo_logistic werkzeug: 192.168.177.1 - - [13/Jan/2018 09:11:02] "GET /web/content/441-663d39a/web.assets_frontend.0.css HTTP/1.1" 200 -
2018-01-13 09:11:02,137 1 INFO odoo_logistic werkzeug: 192.168.177.1 - - [13/Jan/2018 09:11:02] "GET /web/content/436-03967ef/web.assets_common.0.css HTTP/1.1" 200 -
2018-01-13 09:11:02,162 1 INFO odoo_logistic werkzeug: 192.168.177.1 - - [13/Jan/2018 09:11:02] "GET /web/content/444-663d39a/web.assets_frontend.js HTTP/1.1" 200 -
2018-01-13 09:11:02,215 1 INFO odoo_logistic werkzeug: 192.168.177.1 - - [13/Jan/2018 09:11:02] "GET /web/content/445-a27b1f9/website.assets_editor.js HTTP/1.1" 200 -
2018-01-13 09:11:02,250 1 INFO odoo_logistic werkzeug: 192.168.177.1 - - [13/Jan/2018 09:11:02] "GET /web/content/439-03967ef/web.assets_common.js HTTP/1.1" 304 -
2018-01-13 09:11:02,595 1 INFO odoo_logistic werkzeug: 192.168.177.1 - - [13/Jan/2018 09:11:02] "POST /web/dataset/call HTTP/1.1" 200 -
2018-01-13 09:11:02,664 1 INFO odoo_logistic werkzeug: 192.168.177.1 - - [13/Jan/2018 09:11:02] "POST /website/translations HTTP/1.1" 200 -
2018-01-13 09:11:02,686 1 INFO odoo_logistic werkzeug: 192.168.177.1 - - [13/Jan/2018 09:11:02] "POST /web/dataset/call_kw/web_tour.tour/get_consumed_tours HTTP/1.1" 200 -
2018-01-13 09:11:02,689 1 INFO ? werkzeug: 192.168.177.1 - - [13/Jan/2018 09:11:02] "GET /website/static/src/xml/website.xml HTTP/1.1" 200 -
2018-01-13 09:11:02,708 1 INFO ? werkzeug: 192.168.177.1 - - [13/Jan/2018 09:11:02] "GET /website/static/src/xml/website.editor.xml HTTP/1.1" 200 -
2018-01-13 09:11:02,774 1 INFO ? werkzeug: 192.168.177.1 - - [13/Jan/2018 09:11:02] "GET /web_editor/static/src/xml/editor.xml HTTP/1.1" 200 -
2018-01-13 09:11:02,821 1 INFO ? werkzeug: 192.168.177.1 - - [13/Jan/2018 09:11:02] "GET /web_planner/static/src/xml/web_planner.xml HTTP/1.1" 200 -
2018-01-13 09:11:02,853 1 INFO ? werkzeug: 192.168.177.1 - - [13/Jan/2018 09:11:02] "GET /web_tour/static/src/xml/tip.xml HTTP/1.1" 200 -
2018-01-13 09:11:02,884 1 INFO odoo_logistic werkzeug: 192.168.177.1 - - [13/Jan/2018 09:11:02] "POST /web/dataset/call_kw/web.planner/search_read HTTP/1.1" 200 -
2018-01-13 09:11:05,906 1 INFO odoo_logistic odoo.addons.base.ir.ir_attachment: _read_file reading /var/lib/odoo/filestore/odoo_logistic/bd/bd402be51199b5dbe8b8019aaa197ff08384cf31
Traceback (most recent call last):
  File "/usr/lib/python3/dist-packages/odoo/tools/cache.py", line 84, in lookup
    r = d[key]
  File "/usr/lib/python3/dist-packages/odoo/tools/func.py", line 68, in wrapper
    return func(self, *args, **kwargs)
  File "/usr/lib/python3/dist-packages/odoo/tools/lru.py", line 44, in __getitem__
    a = self.d[obj].me
KeyError: ('ir.ui.menu', <function IrUiMenu.load_menus at 0x7f29b4125598>, 1, False, ('en_US',))

During handling of the above exception, another exception occurred:

Traceback (most recent call last):
  File "/usr/lib/python3/dist-packages/odoo/fields.py", line 944, in __get__
    value = record.env.cache.get(record, self)
  File "/usr/lib/python3/dist-packages/odoo/api.py", line 960, in get
    value = self._data[field][record.id][key]
KeyError: <odoo.api.Environment object at 0x7f29aee61470>

During handling of the above exception, another exception occurred:

Traceback (most recent call last):
  File "/usr/lib/python3/dist-packages/odoo/addons/base/ir/ir_attachment.py", line 100, in _file_read
    r = base64.b64encode(open(full_path,'rb').read())
FileNotFoundError: [Errno 2] No such file or directory: '/var/lib/odoo/filestore/odoo_logistic/bd/bd402be51199b5dbe8b8019aaa197ff08384cf31'
2018-01-13 09:11:05,907 1 INFO odoo_logistic odoo.addons.base.ir.ir_attachment: _read_file reading /var/lib/odoo/filestore/odoo_logistic/9c/9c47efe86d2251992fa7a68a4e8a206f33e5949d
Traceback (most recent call last):
  File "/usr/lib/python3/dist-packages/odoo/tools/cache.py", line 84, in lookup
    r = d[key]
  File "/usr/lib/python3/dist-packages/odoo/tools/func.py", line 68, in wrapper
    return func(self, *args, **kwargs)
  File "/usr/lib/python3/dist-packages/odoo/tools/lru.py", line 44, in __getitem__
    a = self.d[obj].me
KeyError: ('ir.ui.menu', <function IrUiMenu.load_menus at 0x7f29b4125598>, 1, False, ('en_US',))

During handling of the above exception, another exception occurred:

Traceback (most recent call last):
  File "/usr/lib/python3/dist-packages/odoo/fields.py", line 944, in __get__
    value = record.env.cache.get(record, self)
  File "/usr/lib/python3/dist-packages/odoo/api.py", line 960, in get
    value = self._data[field][record.id][key]
KeyError: <odoo.api.Environment object at 0x7f29aee61470>

During handling of the above exception, another exception occurred:

Traceback (most recent call last):
  File "/usr/lib/python3/dist-packages/odoo/addons/base/ir/ir_attachment.py", line 100, in _file_read
    r = base64.b64encode(open(full_path,'rb').read())
FileNotFoundError: [Errno 2] No such file or directory: '/var/lib/odoo/filestore/odoo_logistic/9c/9c47efe86d2251992fa7a68a4e8a206f33e5949d'
2018-01-13 09:11:07,438 1 INFO odoo_logistic werkzeug: 192.168.177.1 - - [13/Jan/2018 09:11:07] "GET /web HTTP/1.1" 200 -
2018-01-13 09:11:07,658 1 INFO odoo_logistic werkzeug: 192.168.177.1 - - [13/Jan/2018 09:11:07] "GET /web/content/446-c7bfac4/web.assets_backend.0.css HTTP/1.1" 200 -
2018-01-13 09:11:07,681 1 INFO odoo_logistic werkzeug: 192.168.177.1 - - [13/Jan/2018 09:11:07] "GET /web/content/450-c7bfac4/web.assets_backend.js HTTP/1.1" 200 -
2018-01-13 09:11:07,686 1 INFO odoo_logistic werkzeug: 192.168.177.1 - - [13/Jan/2018 09:11:07] "GET /web/content/447-c7bfac4/web.assets_backend.1.css HTTP/1.1" 200 -
2018-01-13 09:11:08,317 1 INFO odoo_logistic werkzeug: 192.168.177.1 - - [13/Jan/2018 09:11:08] "POST /web/dataset/call HTTP/1.1" 200 -
2018-01-13 09:11:08,469 1 INFO odoo_logistic werkzeug: 192.168.177.1 - - [13/Jan/2018 09:11:08] "GET /web/webclient/qweb?mods=web,base,web_editor,web_planner,bus,web_tour,mail,portal,website,al_website,website_theme_install,theme_bootswatch,base_import,website_mail,web_settings_dashboard,web_kanban_gauge,iap,auth_signup,web_diagram HTTP/1.1" 200 -
2018-01-13 09:11:08,522 1 INFO odoo_logistic werkzeug: 192.168.177.1 - - [13/Jan/2018 09:11:08] "POST /web/webclient/translations HTTP/1.1" 200 -
2018-01-13 09:11:08,659 1 INFO odoo_logistic odoo.addons.base.ir.ir_attachment: _read_file reading /var/lib/odoo/filestore/odoo_logistic/49/492128466be63cd22c92773235330fefbf762bec
Traceback (most recent call last):
  File "/usr/lib/python3/dist-packages/odoo/fields.py", line 944, in __get__
    value = record.env.cache.get(record, self)
  File "/usr/lib/python3/dist-packages/odoo/api.py", line 960, in get
    value = self._data[field][record.id][key]
KeyError: <odoo.api.Environment object at 0x7f29af1132b0>

During handling of the above exception, another exception occurred:

Traceback (most recent call last):
  File "/usr/lib/python3/dist-packages/odoo/fields.py", line 944, in __get__
    value = record.env.cache.get(record, self)
  File "/usr/lib/python3/dist-packages/odoo/api.py", line 960, in get
    value = self._data[field][record.id][key]
KeyError: <odoo.api.Environment object at 0x7f29af1132b0>

During handling of the above exception, another exception occurred:

Traceback (most recent call last):
  File "/usr/lib/python3/dist-packages/odoo/fields.py", line 944, in __get__
    value = record.env.cache.get(record, self)
  File "/usr/lib/python3/dist-packages/odoo/api.py", line 960, in get
    value = self._data[field][record.id][key]
KeyError: <odoo.api.Environment object at 0x7f29af1132b0>

During handling of the above exception, another exception occurred:

Traceback (most recent call last):
  File "/usr/lib/python3/dist-packages/odoo/addons/base/ir/ir_attachment.py", line 100, in _file_read
    r = base64.b64encode(open(full_path,'rb').read())
FileNotFoundError: [Errno 2] No such file or directory: '/var/lib/odoo/filestore/odoo_logistic/49/492128466be63cd22c92773235330fefbf762bec'
2018-01-13 09:11:08,663 1 INFO odoo_logistic werkzeug: 192.168.177.1 - - [13/Jan/2018 09:11:08] "POST /web/dataset/call_kw/res.users/activity_user_count HTTP/1.1" 200 -
2018-01-13 09:11:08,687 1 INFO odoo_logistic werkzeug: 192.168.177.1 - - [13/Jan/2018 09:11:08] "GET /web/image?model=res.users&field=image_small&id=1 HTTP/1.1" 304 -
2018-01-13 09:11:08,762 1 INFO odoo_logistic werkzeug: 192.168.177.1 - - [13/Jan/2018 09:11:08] "POST /mail/client_action HTTP/1.1" 200 -
2018-01-13 09:11:08,802 1 INFO odoo_logistic werkzeug: 192.168.177.1 - - [13/Jan/2018 09:11:08] "POST /web/dataset/call_kw/web.planner/search_read HTTP/1.1" 200 -
2018-01-13 09:11:08,916 1 INFO odoo_logistic werkzeug: 192.168.177.1 - - [13/Jan/2018 09:11:08] "POST /web/action/load HTTP/1.1" 200 -
2018-01-13 09:11:09,230 1 INFO odoo_logistic werkzeug: 192.168.177.1 - - [13/Jan/2018 09:11:09] "POST /web/dataset/call_kw/ir.module.module/load_views HTTP/1.1" 200 -
2018-01-13 09:11:09,302 1 INFO odoo_logistic werkzeug: 192.168.177.1 - - [13/Jan/2018 09:11:09] "POST /web/dataset/search_read HTTP/1.1" 200 -
2018-01-13 09:11:09,646 1 INFO ? werkzeug: 192.168.177.1 - - [13/Jan/2018 09:11:09] "GET /al_website/static/description/icon.png HTTP/1.1" 200 -
2018-01-13 09:11:10,805 1 INFO odoo_logistic werkzeug: 192.168.177.1 - - [13/Jan/2018 09:11:10] "POST /web/action/load HTTP/1.1" 200 -
2018-01-13 09:11:10,878 1 INFO odoo_logistic werkzeug: 192.168.177.1 - - [13/Jan/2018 09:11:10] "POST /web/action/run HTTP/1.1" 200 -
2018-01-13 09:11:10,929 1 INFO ? werkzeug: 192.168.177.1 - - [13/Jan/2018 09:11:10] "GET /web/static/lib/nvd3/nv.d3.css HTTP/1.1" 200 -
2018-01-13 09:11:10,937 1 INFO ? werkzeug: 192.168.177.1 - - [13/Jan/2018 09:11:10] "GET /web/static/lib/nvd3/d3.v3.js HTTP/1.1" 200 -
2018-01-13 09:11:11,033 1 INFO ? werkzeug: 192.168.177.1 - - [13/Jan/2018 09:11:11] "GET /web/static/lib/nvd3/nv.d3.js HTTP/1.1" 200 -
2018-01-13 09:11:11,094 1 INFO ? werkzeug: 192.168.177.1 - - [13/Jan/2018 09:11:11] "GET /web/static/src/js/libs/nvd3.js HTTP/1.1" 200 -
2018-01-13 09:11:11,384 1 INFO odoo_logistic werkzeug: 192.168.177.1 - - [13/Jan/2018 09:11:11] "POST /website/fetch_dashboard_data HTTP/1.1" 200 -
2018-01-13 09:11:12,269 1 INFO odoo_logistic werkzeug: 192.168.177.1 - - [13/Jan/2018 09:11:12] "POST /web/dataset/search_read HTTP/1.1" 200 -
2018-01-13 09:11:14,121 1 INFO odoo_logistic werkzeug: 192.168.177.1 - - [13/Jan/2018 09:11:14] "POST /web/action/run HTTP/1.1" 200 -
2018-01-13 09:11:14,351 1 INFO odoo_logistic werkzeug: 192.168.177.1 - - [13/Jan/2018 09:11:14] "POST /website/fetch_dashboard_data HTTP/1.1" 200 -
2018-01-13 09:11:17,098 1 INFO odoo_logistic werkzeug: 192.168.177.1 - - [13/Jan/2018 09:11:17] "POST /web/dataset/search_read HTTP/1.1" 200 -
2018-01-13 09:11:18,793 1 INFO odoo_logistic werkzeug: 192.168.177.1 - - [13/Jan/2018 09:11:18] "POST /web/dataset/search_read HTTP/1.1" 200 -
2018-01-13 09:11:20,855 1 INFO odoo_logistic werkzeug: 192.168.177.1 - - [13/Jan/2018 09:11:20] "POST /web/dataset/search_read HTTP/1.1" 200 -
2018-01-13 09:11:21,904 1 INFO odoo_logistic werkzeug: 192.168.177.1 - - [13/Jan/2018 09:11:21] "POST /web/dataset/search_read HTTP/1.1" 200 -
2018-01-13 09:11:27,814 1 INFO odoo_logistic werkzeug: 192.168.177.1 - - [13/Jan/2018 09:11:27] "POST /web/dataset/search_read HTTP/1.1" 200 -
2018-01-13 09:11:41,032 1 INFO odoo_logistic werkzeug: 192.168.177.1 - - [13/Jan/2018 09:11:41] "POST /web/dataset/call_kw/ir.filters/create_or_replace HTTP/1.1" 200 -
2018-01-13 09:11:43,045 1 INFO odoo_logistic werkzeug: 192.168.177.1 - - [13/Jan/2018 09:11:43] "GET /web HTTP/1.1" 200 -
2018-01-13 09:11:43,212 1 INFO odoo_logistic werkzeug: 192.168.177.1 - - [13/Jan/2018 09:11:43] "GET /web/content/436-03967ef/web.assets_common.0.css HTTP/1.1" 200 -
2018-01-13 09:11:43,220 1 INFO odoo_logistic werkzeug: 192.168.177.1 - - [13/Jan/2018 09:11:43] "GET /web/content/446-c7bfac4/web.assets_backend.0.css HTTP/1.1" 200 -
2018-01-13 09:11:43,224 1 INFO odoo_logistic werkzeug: 192.168.177.1 - - [13/Jan/2018 09:11:43] "GET /web/content/363-cade463/web_editor.summernote.0.css HTTP/1.1" 200 -
2018-01-13 09:11:43,253 1 INFO odoo_logistic werkzeug: 192.168.177.1 - - [13/Jan/2018 09:11:43] "GET /web/content/447-c7bfac4/web.assets_backend.1.css HTTP/1.1" 200 -
2018-01-13 09:11:43,315 1 INFO odoo_logistic werkzeug: 192.168.177.1 - - [13/Jan/2018 09:11:43] "GET /web/content/364-c8e0d48/web_editor.assets_editor.0.css HTTP/1.1" 200 -
2018-01-13 09:11:43,495 1 INFO odoo_logistic werkzeug: 192.168.177.1 - - [13/Jan/2018 09:11:43] "GET /web/content/439-03967ef/web.assets_common.js HTTP/1.1" 200 -
2018-01-13 09:11:43,502 1 INFO odoo_logistic werkzeug: 192.168.177.1 - - [13/Jan/2018 09:11:43] "GET /web/content/450-c7bfac4/web.assets_backend.js HTTP/1.1" 200 -
2018-01-13 09:11:43,543 1 INFO odoo_logistic werkzeug: 192.168.177.1 - - [13/Jan/2018 09:11:43] "GET /web/content/366-cade463/web_editor.summernote.js HTTP/1.1" 200 -
2018-01-13 09:11:43,547 1 INFO odoo_logistic werkzeug: 192.168.177.1 - - [13/Jan/2018 09:11:43] "GET /web/content/367-c8e0d48/web_editor.assets_editor.js HTTP/1.1" 200 -
2018-01-13 09:11:43,674 1 INFO odoo_logistic werkzeug: 192.168.177.1 - - [13/Jan/2018 09:11:43] "GET /web/binary/company_logo HTTP/1.1" 200 -
2018-01-13 09:11:44,067 1 INFO odoo_logistic werkzeug: 192.168.177.1 - - [13/Jan/2018 09:11:44] "GET /web/webclient/qweb?mods=web,base,web_editor,web_planner,bus,web_tour,mail,portal,website,al_website,website_theme_install,theme_bootswatch,base_import,website_mail,web_settings_dashboard,web_kanban_gauge,iap,auth_signup,web_diagram HTTP/1.1" 200 -
2018-01-13 09:11:44,103 1 INFO odoo_logistic werkzeug: 192.168.177.1 - - [13/Jan/2018 09:11:44] "POST /web/dataset/call HTTP/1.1" 200 -
2018-01-13 09:11:44,193 1 INFO ? werkzeug: 192.168.177.1 - - [13/Jan/2018 09:11:44] "GET /web/static/src/img/favicon.ico HTTP/1.1" 200 -
2018-01-13 09:11:44,246 1 INFO odoo_logistic werkzeug: 192.168.177.1 - - [13/Jan/2018 09:11:44] "POST /web/webclient/translations HTTP/1.1" 200 -
2018-01-13 09:11:44,429 1 INFO ? werkzeug: 192.168.177.1 - - [13/Jan/2018 09:11:44] "GET /web/static/lib/fontawesome/fonts/fontawesome-webfont.woff2?v=4.7.0 HTTP/1.1" 200 -
2018-01-13 09:11:44,466 1 INFO odoo_logistic werkzeug: 192.168.177.1 - - [13/Jan/2018 09:11:44] "POST /web/dataset/call_kw/res.users/activity_user_count HTTP/1.1" 200 -
2018-01-13 09:11:44,541 1 INFO odoo_logistic odoo.addons.base.ir.ir_attachment: _read_file reading /var/lib/odoo/filestore/odoo_logistic/49/492128466be63cd22c92773235330fefbf762bec
Traceback (most recent call last):
  File "/usr/lib/python3/dist-packages/odoo/fields.py", line 944, in __get__
    value = record.env.cache.get(record, self)
  File "/usr/lib/python3/dist-packages/odoo/api.py", line 960, in get
    value = self._data[field][record.id][key]
KeyError: <odoo.api.Environment object at 0x7f2990d17710>

During handling of the above exception, another exception occurred:

Traceback (most recent call last):
  File "/usr/lib/python3/dist-packages/odoo/fields.py", line 944, in __get__
    value = record.env.cache.get(record, self)
  File "/usr/lib/python3/dist-packages/odoo/api.py", line 960, in get
    value = self._data[field][record.id][key]
KeyError: <odoo.api.Environment object at 0x7f2990d17710>

During handling of the above exception, another exception occurred:

Traceback (most recent call last):
  File "/usr/lib/python3/dist-packages/odoo/fields.py", line 944, in __get__
    value = record.env.cache.get(record, self)
  File "/usr/lib/python3/dist-packages/odoo/api.py", line 960, in get
    value = self._data[field][record.id][key]
KeyError: <odoo.api.Environment object at 0x7f2990d17710>

During handling of the above exception, another exception occurred:

Traceback (most recent call last):
  File "/usr/lib/python3/dist-packages/odoo/addons/base/ir/ir_attachment.py", line 100, in _file_read
    r = base64.b64encode(open(full_path,'rb').read())
FileNotFoundError: [Errno 2] No such file or directory: '/var/lib/odoo/filestore/odoo_logistic/49/492128466be63cd22c92773235330fefbf762bec'
2018-01-13 09:11:44,577 1 INFO odoo_logistic werkzeug: 192.168.177.1 - - [13/Jan/2018 09:11:44] "GET /web/image?model=res.users&field=image_small&id=1 HTTP/1.1" 304 -
2018-01-13 09:11:44,582 1 INFO odoo_logistic werkzeug: 192.168.177.1 - - [13/Jan/2018 09:11:44] "POST /web/dataset/call_kw/web.planner/search_read HTTP/1.1" 200 -
2018-01-13 09:11:44,591 1 INFO odoo_logistic werkzeug: 192.168.177.1 - - [13/Jan/2018 09:11:44] "POST /mail/client_action HTTP/1.1" 200 -
2018-01-13 09:11:44,643 1 INFO odoo_logistic werkzeug: 192.168.177.1 - - [13/Jan/2018 09:11:44] "POST /web/action/load HTTP/1.1" 200 -
2018-01-13 09:11:44,844 1 INFO odoo_logistic werkzeug: 192.168.177.1 - - [13/Jan/2018 09:11:44] "POST /web/dataset/call_kw/ir.module.module/load_views HTTP/1.1" 200 -
2018-01-13 09:11:44,933 1 INFO odoo_logistic werkzeug: 192.168.177.1 - - [13/Jan/2018 09:11:44] "POST /web/dataset/search_read HTTP/1.1" 200 -
2018-01-13 09:11:46,747 1 INFO odoo_logistic werkzeug: 192.168.177.1 - - [13/Jan/2018 09:11:46] "POST /web/dataset/call_kw/ir.module.module/read HTTP/1.1" 200 -
2018-01-13 09:11:46,792 1 INFO odoo_logistic werkzeug: 192.168.177.1 - - [13/Jan/2018 09:11:46] "POST /web/dataset/call_kw/ir.module.module.dependency/read HTTP/1.1" 200 -
2018-01-13 09:11:46,909 1 INFO odoo_logistic werkzeug: 192.168.177.1 - - [13/Jan/2018 09:11:46] "POST /web/dataset/call_kw/ir.module.category/name_search HTTP/1.1" 200 -
2018-01-13 09:11:47,027 1 INFO ? werkzeug: 192.168.177.1 - - [13/Jan/2018 09:11:47] "GET /base/static/src/css/description.css HTTP/1.1" 200 -
2018-01-13 09:11:58,853 1 INFO odoo_logistic werkzeug: 192.168.177.1 - - [13/Jan/2018 09:11:58] "POST /longpolling/poll HTTP/1.1" 200 -
2018-01-13 09:12:34,659 1 INFO odoo_logistic werkzeug: 192.168.177.1 - - [13/Jan/2018 09:12:34] "POST /longpolling/poll HTTP/1.1" 200 -
